Workbook
Name A999999999: 'Instruction Set'!$AAK$2
Name CurFolder: CPU!$A$1
Name XFD1048590: 'Instruction Set'!#REF!
Name XFD1048600: 'Instruction Set'!#REF!
Name XFD1048700: 'Instruction Set'!#REF!
Name XFD1049000: 'Instruction Set'!#REF!
Name XFD1050000: 'Instruction Set'!#REF!
Name XFD1100000: 'Instruction Set'!#REF!
Name XFD1999999: 'Instruction Set'!#REF!
Name XFD9999999: 'Instruction Set'!#REF!
Name XFE1: 'Instruction Set'!$XAJ$2
Name XFF1: 'Instruction Set'!$XAJ$2
Name XFG1: 'Instruction Set'!#REF!
Name XGG1: 'Instruction Set'!$XAJ$2
Name XZZ1: 'Instruction Set'!$QAJ$2
Name ZZZ1: 'Instruction Set'!$A$100027
Name ZZZZ1: 'Instruction Set'!$A$100027
Name ZZZZZ: 'Instruction Set'!$A$100027
Name ZZZZZ1: 'Instruction Set'!$A$100027

Sheet CPU
A1: {=LEFT(CELL("filename"),FIND("[",CELL("filename"))-1)} -> C:\ | H1: Reset | J1: Clock EN | L1: Clock | N1: Halted
H2: TRUE | J2: FALSE | L2: =IF(H2,0,IF(J2,IF(L2=0,1,0),L2)) -> 0 | N2: =D51 -> FALSE
B4: Interrupt Controller
B6: Clock | D6: Reset | F6: Ack | H6: IRQ0 | J6: IRQ1 | L6: IRQ2 | N6: IRQ3
B7: =$L$2 -> 0 | D7: =$H$2 -> TRUE | F7: =AP82 -> FALSE | H7: =Contoller!B19 -> 0 | J7: 0 | L7: 0 | N7: 0
B9: Interrupt Id | H9: IRQ0 | J9: IRQ1 | L9: IRQ2 | N9: IRQ3
B10: =IF($D$7,0,IF($H$10=1,0,IF($J$10=1,0,IF($L$10=1,1,IF($N$10=1,1,0))))) -> 0 | C10: =IF($D$7,0,IF($H$10=1,0,IF($J$10=1,1,IF($L$10=1,0,IF($N$10=1,1,0))))) -> 0 | H10: =IF($D$7,0,IF(H7,1,IF($B$7,IF($F$7,IF($B$10=0,IF($C$10=0,0,H10),H10),H10),H10))) -> 0 | J10: =IF($D$7,0,IF(F7,0,IF(J7,1,IF($B$7,IF($F$7,IF($B$10=0,IF($C$10=0,0,J10),J10),J10),J10)))) -> 0 | L10: =IF($D$7,0,IF(H7,0,IF(L7,1,IF($B$7,IF($F$7,IF($B$10=0,IF($C$10=0,0,L10),L10),L10),L10)))) -> 0 | N10: =IF($D$7,0,IF(J7,0,IF(N7,1,IF($B$7,IF($F$7,IF($B$10=0,IF($C$10=0,0,N10),N10),N10),N10)))) -> 0
D12: Pending | I12: Interrupt Id
D13: =OR(H10,J10,L10,N10) -> FALSE | I13: =B10 -> 0 | J13: =C10 -> 0
B16: Status Register Output | M16: Interrupt Logic
B18: Clock | D18: Reset | F18: Carry | G18: Negative | H18: Overflow | I18: Zero | J18: Last Int | K18: Interrupt | M18: Clock | O18: Enable | Q18: Pending | S18: Interrupt Id
B19: =L2 -> 0 | D19: =H2 -> TRUE | F19: =IF(D19,0,IF($B$19,AH228,F19)) -> 0 | G19: =IF(D19,0,IF($B$19,AJ228,G19)) -> 0 | H19: =IF(D19,0,IF($B$19,AH229,H19)) -> 0 | I19: =IF(D19,0,IF($B$19,AJ229,I19)) -> 0 | J19: =IF(D19,0,IF(M19,K19,J19)) -> 0 | K19: =IF(D19,0,IF($B$19,AH230,K19)) -> 0 | M19: =L2 -> 0 | O19: =IF(M19,IF(K19,AO82,NOT(J19)),O19) -> TRUE | Q19: =IF($M$19,D13,Q19) -> FALSE | S19: =IF($M$19,I13,S19) -> 0 | T19: =IF($M$19,J13,T19) -> 0
M21: Override | O21: ISR Address | AB21: Set Flag | AC21: Int Flag
M22: =AND(O19,Q19) -> FALSE | O22: 0 | P22: 0 | Q22: 0 | R22: 0 | S22: 0 | T22: 0 | U22: 0 | V22: 0 | W22: 0 | X22: 0 | Y22: =S19 -> 0 | Z22: =T19 -> 0 | AB22: =M22 -> FALSE | AC22: =M22 -> FALSE
B25: Instruction Fetch
T26: Instruction Override
C27: Clock | E27: Address
C28: =L2 -> 0 | E28: =M261 -> 0 | F28: =N261 -> 0 | G28: =O261 -> 0 | H28: =P261 -> 0 | I28: =Q261 -> 0 | J28: =R261 -> 0 | K28: =S261 -> 0 | L28: =T261 -> 0 | ... P28: =X261 -> 0 | T28: Override | V28: Instruction
E29: =(E28*128)+(F28*64)+(G28*32)+(H28*16)+(I28*8)+(J28*4)+(K28*2)+(L28*1)+1 -> 1 | I29: =(((I28*8)+(J28*4)+(K28*2)+(L28*1))*16)+1 -> 1 | M29: =(((M28*8)+(N28*4)+(O28*2)+(P28*1))*16)+1 -> 65 | T29: FALSE | V29: 0 | W29: 0 | X29: 0 | Y29: 0 | Z29: 0 | AA29: 0 | AB29: 0 | AC29: 0 | AD29: 0 | AE29: 0 | AF29: 0 | AG29: 0 | AH29: 0 | AI29: 0 | AJ29: 0 | AK29: 0
B30: ROM Output
B31: {=INDEX(ROM[],$E$29,$M$29+(COLUMN()-COLUMN($B$31)))} -> 0 | C31: {=INDEX(ROM[],$E$29,$M$29+(COLUMN()-COLUMN($B$31)))} -> 0 | D31: {=INDEX(ROM[],$E$29,$M$29+(COLUMN()-COLUMN($B$31)))} -> 1 | E31: {=INDEX(ROM[],$E$29,$M$29+(COLUMN()-COLUMN($B$31)))} -> 0 | F31: {=INDEX(ROM[],$E$29,$M$29+(COLUMN()-COLUMN($B$31)))} -> 1 | G31: {=INDEX(ROM[],$E$29,$M$29+(COLUMN()-COLUMN($B$31)))} -> 1 | H31: {=INDEX(ROM[],$E$29,$M$29+(COLUMN()-COLUMN($B$31)))} -> 1 | I31: {=INDEX(ROM[],$E$29,$M$29+(COLUMN()-COLUMN($B$31)))} -> 1 | ... Q31: {=INDEX(ROM[],$E$29,$M$29+(COLUMN()-COLUMN($B$31)))} -> 1
B34: Control Unit
K36: Clock | M36: Reset | O36: Instruction | AF36: Interrupt | AQ36: Set Flag | AR36: Int Flag
K37: =L2 -> 0 | M37: =H2 -> TRUE | O37: =IF($M$37,0,IF($T$29,V29,IF($K$37,IF(AND($AN$82,$D$89),F89,B31),O37))) -> 0 | P37: =IF($M$37,0,IF($T$29,W29,IF($K$37,IF(AND($AN$82,$D$89),G89,C31),P37))) -> 0 | Q37: =IF($M$37,0,IF($T$29,X29,IF($K$37,IF(AND($AN$82,$D$89),H89,D31),Q37))) -> 0 | R37: =IF($M$37,0,IF($T$29,Y29,IF($K$37,IF(AND($AN$82,$D$89),I89,E31),R37))) -> 0 | S37: =IF($M$37,0,IF($T$29,Z29,IF($K$37,IF(AND($AN$82,$D$89),J89,F31),S37))) -> 0 | T37: =IF($M$37,0,IF($T$29,AA29,IF($K$37,IF(AND($AN$82,$D$89),K89,G31),T37))) -> 0 | U37: =IF($M$37,0,IF($T$29,AB29,IF($K$37,IF(AND($AN$82,$D$89),L89,H31),U37))) -> 0 | V37: =IF($M$37,0,IF($T$29,AC29,IF($K$37,IF(AND($AN$82,$D$89),M89,I31),V37))) -> 0 | ... AD37: =IF($M$37,0,IF($T$29,AK29,IF($K$37,IF(AND($AN$82,$D$89),U89,Q31),AD37))) -> 0 | AF37: =M22 -> FALSE | AQ37: =AB22 -> FALSE | AR37: =AC22 -> FALSE
P38: =(P37*4)+(Q37*2)+(R37*1) -> 0 | S38: =(S37*8)+(T37*4)+(U37*2)+(V37*1) -> 0 | AA38: =(AA37*8)+(AB37*4)+(AC37*2)+(AD37*1) -> 0
P39: =(P37*2)+(Q37*1) -> 0 | S39: =(S37*4)+(T37*2)+(U37*1) -> 0 | AA39: =(AA37*4)+(AB37*2)+(AC37*1) -> 0
S41: Immediate Address
S42: =IF($AF$37,O22,S37) -> 0 | T42: =IF($AF$37,P22,T37) -> 0 | U42: =IF($AF$37,Q22,U37) -> 0 | V42: =IF($AF$37,R22,V37) -> 0 | W42: =IF($AF$37,S22,W37) -> 0 | X42: =IF($AF$37,T22,X37) -> 0 | Y42: =IF($AF$37,U22,Y37) -> 0 | Z42: =IF($AF$37,V22,Z37) -> 0 | ... AD42: =IF($AF$37,Z22,AD37) -> 0
D44: Interrupt
D45: =AF37 -> FALSE
Q46: Memory Write Mux | S46: Push PC | W46: Mem In | X46: PC Hold | Z46: PC OV | AB46: Stack En | AC46: Stack Set
Q47: 0 | R47: =D45 -> FALSE | S47: =D45 -> FALSE | W47: =D45 -> FALSE | X47: =D45 -> FALSE | Z47: =D45 -> FALSE | AB47: =D45 -> FALSE | AC47: 0
B48: 0xxx | C48: =NOT(O37) -> TRUE | D48: 0000
D49: =IF(C48, P38=0, 0) -> TRUE
D50: HLT
D51: =IF(D49,AA38=1,0) -> FALSE
D52: 0001
D53: =IF(C48, P38=1, 0) -> FALSE
D54: Reg Out 1 | E54: Reg Out 2 | G54: Mem Out | H54: I/O Out | I54: ALU Mux 1 | K54: ALU Mux 2 | M54: Register Input Mux | O54: Memory Read Mux | Q54: Memory Write Mux | V54: Reg In | W54: Mem In | AB54: Stack En | AC54: Stack Set | AD54: I/O In | AE54: ALU EN | AF54: ALU Opcode | AJ54: Carry | AK54: Negative | AL54: Overflow | AM54: Zero
D55: =IF(D53, OR(AA38=1, AA38=2, AA38=5), 0) -> 0 | E55: =IF(D53, AA38<=1,0) -> 0 | G55: =IF(D53, AA38=3, 0) -> 0 | H55: =IF(D53, AA38=4, 0) -> 0 | I55: =IF(D53, AA38=1, 0) -> 0 | J55: 0 | K55: 0 | L55: =IF(D53, AA38<=1, 0) -> 0 | M55: =IF(D53,AA38=3) -> FALSE | N55: =IF(D53,AA38=4) -> FALSE | O55: 0 | P55: =IF(D53,AA38=3) -> FALSE | Q55: 0 | R55: =IF(D53,AA38=2) -> FALSE | V55: =IF(D53,OR(AA38=0,AA38=3,AA38=4)) -> FALSE | W55: =IF(D53,AA38=2) -> FALSE | AB55: =IF(D53, OR(AA38=2,AA38=3),0) -> 0 | AC55: =IF(D53,AA38=3,0) -> 0 | AD55: =IF(D53, AA38=5, 0) -> 0 | AE55: =IF(D53,AA38=1) -> FALSE | AF55: 0 | AG55: 0 | AH55: 0 | AI55: =IF(D53,AA38=1) -> FALSE | AJ55: =IF(D53,AA38=1) -> FALSE | AK55: =IF(D53,AA38=1) -> FALSE | AL55: =IF(D53,AA38=1) -> FALSE | AM55: =IF(D53,AA38=1) -> FALSE
...

Sheet Contoller
B1: Controller
B3: Clock
B4: =IF(CPU!H2,0,IF(B4,0,1)) -> 0
C6: =ABS(C9-E12) -> 0 | D6: =ABS(D9-D13) -> 0 | E6: =ABS(E9-F13) -> 0 | F6: =ABS(F9-E14) -> 0
C8: Last State
C9: =IF($B$4,ABS(E12),C9) -> 0 | D9: =IF($B$4,ABS(D13),D9) -> 0 | E9: =IF($B$4,ABS(F13),E9) -> 0 | F9: =IF($B$4,ABS(E14),F9) -> 0
E11: Up
E12: FALSE
C13: Left | D13: FALSE | F13: FALSE | G13: Right
E14: FALSE
E15: Down
B18: IRQ | E18: State
B19: =ABS(OR(C6:F6)) -> 0 | E19: =ABS(E12) -> 0 | F19: =ABS(D13) -> 0 | G19: =ABS(F13) -> 0 | H19: =ABS(E14) -> 0

Sheet ROM
A1: Column1 | B1: Column2 | C1: Column3 | D1: Column4 | E1: Column5 | F1: Column6 | G1: Column7 | H1: Column8 | I1: Column9 | J1: Column10 | K1: Column11 | L1: Column12 | M1: Column13 | N1: Column14 | O1: Column15 | P1: Column16 | Q1: Column17 | R1: Column18 | S1: Column19 | T1: Column20 | U1: Column21 | V1: Column22 | W1: Column23 | X1: Column24 | Y1: Column25 | Z1: Column26 | AA1: Column27 | AB1: Column28 | AC1: Column29 | AD1: Column30 | AE1: Column31 | AF1: Column32 | AG1: Column33 | AH1: Column34 | AI1: Column35 | AJ1: Column36 | AK1: Column37 | AL1: Column38 | AM1: Column39 | AN1: Column40 | AO1: Column41 | AP1: Column42 | AQ1: Column43 | AR1: Column44 | AS1: Column45 | AT1: Column46 | AU1: Column47 | AV1: Column48 | AW1: Column49 | AX1: Column50 | AY1: Column51 | AZ1: Column52 | BA1: Column53 | BB1: Column54 | BC1: Column55 | BD1: Column56 | BE1: Column57 | BF1: Column58 | BG1: Column59 | BH1: Column60 | BI1: Column61 | BJ1: Column62 | BK1: Column63 | BL1: Column64 | BM1: Column65 | BN1: Column66 | BO1: Column67 | BP1: Column68 | BQ1: Column69 | BR1: Column70 | BS1: Column71 | BT1: Column72 | BU1: Column73 | BV1: Column74 | BW1: Column75 | BX1: Column76 | BY1: Column77 | BZ1: Column78 | CA1: Column79 | CB1: Column80 | CC1: Column81 | CD1: Column82 | CE1: Column83 | CF1: Column84 | CG1: Column85 | CH1: Column86 | CI1: Column87 | CJ1: Column88 | CK1: Column89 | CL1: Column90 | CM1: Column91 | CN1: Column92 | CO1: Column93 | CP1: Column94 | CQ1: Column95 | CR1: Column96 | CS1: Column97 | CT1: Column98 | CU1: Column99 | CV1: Column100 | CW1: Column101 | CX1: Column102 | CY1: Column103 | CZ1: Column104 | DA1: Column105 | DB1: Column106 | DC1: Column107 | DD1: Column108 | DE1: Column109 | DF1: Column110 | DG1: Column111 | DH1: Column112 | DI1: Column113 | DJ1: Column114 | DK1: Column115 | DL1: Column116 | DM1: Column117 | DN1: Column118 | DO1: Column119 | DP1: Column120 | DQ1: Column121 | DR1: Column122 | DS1: Column123 | DT1: Column124 | DU1: Column125 | DV1: Column126 | DW1: Column127 | DX1: Column128 | DY1: Column129 | DZ1: Column130 | EA1: Column131 | EB1: Column132 | EC1: Column133 | ED1: Column134 | EE1: Column135 | EF1: Column136 | EG1: Column137 | EH1: Column138 | EI1: Column139 | EJ1: Column140 | EK1: Column141 | EL1: Column142 | EM1: Column143 | EN1: Column144 | EO1: Column145 | EP1: Column146 | EQ1: Column147 | ER1: Column148 | ES1: Column149 | ET1: Column150 | EU1: Column151 | EV1: Column152 | EW1: Column153 | EX1: Column154 | EY1: Column155 | EZ1: Column156 | FA1: Column157 | FB1: Column158 | FC1: Column159 | FD1: Column160 | FE1: Column161 | FF1: Column162 | FG1: Column163 | FH1: Column164 | FI1: Column165 | FJ1: Column166 | FK1: Column167 | FL1: Column168 | FM1: Column169 | FN1: Column170 | FO1: Column171 | FP1: Column172 | FQ1: Column173 | FR1: Column174 | FS1: Column175 | FT1: Column176 | FU1: Column177 | FV1: Column178 | FW1: Column179 | FX1: Column180 | FY1: Column181 | FZ1: Column182 | GA1: Column183 | GB1: Column184 | GC1: Column185 | GD1: Column186 | GE1: Column187 | GF1: Column188 | GG1: Column189 | GH1: Column190 | GI1: Column191 | GJ1: Column192 | GK1: Column193 | GL1: Column194 | GM1: Column195 | GN1: Column196 | GO1: Column197 | GP1: Column198 | GQ1: Column199 | GR1: Column200 | GS1: Column201 | GT1: Column202 | GU1: Column203 | GV1: Column204 | GW1: Column205 | GX1: Column206 | GY1: Column207 | GZ1: Column208 | HA1: Column209 | HB1: Column210 | HC1: Column211 | HD1: Column212 | HE1: Column213 | HF1: Column214 | HG1: Column215 | HH1: Column216 | HI1: Column217 | HJ1: Column218 | HK1: Column219 | HL1: Column220 | HM1: Column221 | HN1: Column222 | HO1: Column223 | HP1: Column224 | HQ1: Column225 | HR1: Column226 | HS1: Column227 | HT1: Column228 | HU1: Column229 | HV1: Column230 | HW1: Column231 | HX1: Column232 | HY1: Column233 | HZ1: Column234 | IA1: Column235 | IB1: Column236 | IC1: Column237 | ID1: Column238 | IE1: Column239 | IF1: Column240 | IG1: Column241 | IH1: Column242 | II1: Column243 | IJ1: Column244 | IK1: Column245 | IL1: Column246 | IM1: Column247 | IN1: Column248 | IO1: Column249 | IP1: Column250 | IQ1: Column251 | IR1: Column252 | IS1: Column253 | IT1: Column254 | IU1: Column255 | IV1: Column256
A2: 0 | B2: 1 | C2: 1 | D2: 0 | E2: 0 | F2: 0 | G2: 0 | H2: 0 | I2: 0 | J2: 0 | K2: 0 | L2: 0 | M2: 0 | N2: 0 | O2: 0 | P2: 1 | Q2: 0 | R2: 1 | S2: 1 | T2: 0 | U2: 0 | V2: 0 | W2: 0 | X2: 0 | Y2: 0 | Z2: 0 | AA2: 0 | AB2: 0 | AC2: 0 | AD2: 0 | AE2: 0 | AF2: 1 | AG2: 0 | AH2: 1 | AI2: 1 | AJ2: 0 | AK2: 0 | AL2: 0 | AM2: 0 | AN2: 0 | AO2: 0 | AP2: 0 | AQ2: 0 | AR2: 0 | AS2: 0 | AT2: 0 | AU2: 0 | AV2: 1 | AW2: 0 | AX2: 1 | AY2: 1 | AZ2: 0 | BA2: 0 | BB2: 0 | BC2: 0 | BD2: 0 | BE2: 0 | BF2: 0 | BG2: 0 | BH2: 0 | BI2: 0 | BJ2: 0 | BK2: 0 | BL2: 1 | BM2: 0 | BN2: 0 | BO2: 1 | BP2: 0 | BQ2: 1 | BR2: 1 | BS2: 1 | BT2: 1 | BU2: 1 | BV2: 1 | BW2: 1 | BX2: 1 | BY2: 1 | BZ2: 1 | CA2: 1 | CB2: 1 | CC2: 1 | CD2: 1 | CE2: 1 | CF2: 1 | CG2: 1 | CH2: 1 | CI2: 1 | CJ2: 1 | CK2: 0 | CL2: 1 | CM2: 1 | CN2: 1 | CO2: 0 | CP2: 0 | CQ2: 0 | CR2: 0 | CS2: 1 | CT2: 0 | CU2: 1 | CV2: 0 | CW2: 1 | CX2: 1 | CY2: 1 | CZ2: 1 | DA2: 0 | DB2: 0 | DC2: 0 | DD2: 0 | DE2: 0 | DF2: 0 | DG2: 0 | DH2: 1 | DI2: 0 | DJ2: 0 | DK2: 1 | DL2: 0 | DM2: 1 | DN2: 1 | DO2: 1 | DP2: 0 | DQ2: 0 | DR2: 0 | DS2: 0 | DT2: 0 | DU2: 1 | DV2: 0 | DW2: 1 | DX2: 1 | DY2: 0 | DZ2: 1 | EA2: 0 | EB2: 0 | EC2: 0 | ED2: 0 | EE2: 0 | EF2: 0 | EG2: 0 | EH2: 0 | EI2: 0 | EJ2: 0 | EK2: 0 | EL2: 1 | EM2: 0 | EN2: 1 | EO2: 0 | EP2: 0 | EQ2: 0 | ER2: 0 | ES2: 0 | ET2: 0 | EU2: 0 | EV2: 0 | EW2: 0 | EX2: 0 | EY2: 0 | EZ2: 0 | FA2: 0 | FB2: 0 | FC2: 0 | FD2: 0 | FE2: 0 | FF2: 0 | FG2: 0 | FH2: 0 | FI2: 0 | FJ2: 0 | FK2: 0 | FL2: 0 | FM2: 0 | FN2: 0 | FO2: 0 | FP2: 0 | FQ2: 0 | FR2: 0 | FS2: 0 | FT2: 0 | FU2: 0 | FV2: 0 | FW2: 0 | FX2: 0 | FY2: 0 | FZ2: 0 | GA2: 0 | GB2: 0 | GC2: 0 | GD2: 0 | GE2: 0 | GF2: 0 | GG2: 0 | GH2: 0 | GI2: 0 | GJ2: 0 | GK2: 0 | GL2: 0 | GM2: 0 | GN2: 0 | GO2: 0 | GP2: 0 | GQ2: 0 | GR2: 0 | GS2: 0 | GT2: 0 | GU2: 0 | GV2: 0 | GW2: 0 | GX2: 0 | GY2: 0 | GZ2: 0 | HA2: 0 | HB2: 0 | HC2: 0 | HD2: 0 | HE2: 0 | HF2: 0 | HG2: 0 | HH2: 0 | HI2: 0 | HJ2: 0 | HK2: 0 | HL2: 0 | HM2: 0 | HN2: 0 | HO2: 0 | HP2: 0 | HQ2: 0 | HR2: 0 | HS2: 0 | HT2: 0 | HU2: 0 | HV2: 0 | HW2: 0 | HX2: 0 | HY2: 0 | HZ2: 0 | IA2: 0 | IB2: 0 | IC2: 0 | ID2: 0 | IE2: 0 | IF2: 0 | IG2: 0 | IH2: 0 | II2: 0 | IJ2: 0 | IK2: 0 | IL2: 0 | IM2: 0 | IN2: 0 | IO2: 0 | IP2: 0 | IQ2: 0 | IR2: 0 | IS2: 0 | IT2: 0 | IU2: 0 | IV2: 0
A3: 0 | B3: 0 | C3: 0 | D3: 0 | E3: 0 | F3: 0 | G3: 0 | H3: 0 | I3: 0 | J3: 0 | K3: 0 | L3: 0 | M3: 0 | N3: 0 | O3: 0 | P3: 0 | Q3: 0 | R3: 0 | S3: 0 | T3: 0 | U3: 0 | V3: 0 | W3: 0 | X3: 0 | Y3: 0 | Z3: 0 | AA3: 0 | AB3: 0 | AC3: 0 | AD3: 0 | AE3: 0 | AF3: 0 | AG3: 0 | AH3: 0 | AI3: 0 | AJ3: 0 | AK3: 0 | AL3: 0 | AM3: 0 | AN3: 0 | AO3: 0 | AP3: 0 | AQ3: 0 | AR3: 0 | AS3: 0 | AT3: 0 | AU3: 0 | AV3: 0 | AW3: 0 | AX3: 0 | AY3: 0 | AZ3: 0 | BA3: 0 | BB3: 0 | BC3: 0 | BD3: 0 | BE3: 0 | BF3: 0 | BG3: 0 | BH3: 0 | BI3: 0 | BJ3: 0 | BK3: 0 | BL3: 0 | BM3: 0 | BN3: 0 | BO3: 0 | BP3: 0 | BQ3: 0 | BR3: 0 | BS3: 0 | BT3: 0 | BU3: 0 | BV3: 0 | BW3: 0 | BX3: 0 | BY3: 0 | BZ3: 0 | CA3: 0 | CB3: 0 | CC3: 0 | CD3: 0 | CE3: 0 | CF3: 0 | CG3: 0 | CH3: 0 | CI3: 0 | CJ3: 0 | CK3: 0 | CL3: 0 | CM3: 0 | CN3: 0 | CO3: 0 | CP3: 0 | CQ3: 0 | CR3: 0 | CS3: 0 | CT3: 0 | CU3: 0 | CV3: 0 | CW3: 0 | CX3: 0 | CY3: 0 | CZ3: 0 | DA3: 0 | DB3: 0 | DC3: 0 | DD3: 0 | DE3: 0 | DF3: 0 | DG3: 0 | DH3: 0 | DI3: 0 | DJ3: 0 | DK3: 0 | DL3: 0 | DM3: 0 | DN3: 0 | DO3: 0 | DP3: 0 | DQ3: 0 | DR3: 0 | DS3: 0 | DT3: 0 | DU3: 0 | DV3: 0 | DW3: 0 | DX3: 0 | DY3: 0 | DZ3: 0 | EA3: 0 | EB3: 0 | EC3: 0 | ED3: 0 | EE3: 0 | EF3: 0 | EG3: 0 | EH3: 0 | EI3: 0 | EJ3: 0 | EK3: 0 | EL3: 0 | EM3: 0 | EN3: 0 | EO3: 0 | EP3: 0 | EQ3: 0 | ER3: 0 | ES3: 0 | ET3: 0 | EU3: 0 | EV3: 0 | EW3: 0 | EX3: 0 | EY3: 0 | EZ3: 0 | FA3: 0 | FB3: 0 | FC3: 0 | FD3: 0 | FE3: 0 | FF3: 0 | FG3: 0 | FH3: 0 | FI3: 0 | FJ3: 0 | FK3: 0 | FL3: 0 | FM3: 0 | FN3: 0 | FO3: 0 | FP3: 0 | FQ3: 0 | FR3: 0 | FS3: 0 | FT3: 0 | FU3: 0 | FV3: 0 | FW3: 0 | FX3: 0 | FY3: 0 | FZ3: 0 | GA3: 0 | GB3: 0 | GC3: 0 | GD3: 0 | GE3: 0 | GF3: 0 | GG3: 0 | GH3: 0 | GI3: 0 | GJ3: 0 | GK3: 0 | GL3: 0 | GM3: 0 | GN3: 0 | GO3: 0 | GP3: 0 | GQ3: 0 | GR3: 0 | GS3: 0 | GT3: 0 | GU3: 0 | GV3: 0 | GW3: 0 | GX3: 0 | GY3: 0 | GZ3: 0 | HA3: 0 | HB3: 0 | HC3: 0 | HD3: 0 | HE3: 0 | HF3: 0 | HG3: 0 | HH3: 0 | HI3: 0 | HJ3: 0 | HK3: 0 | HL3: 0 | HM3: 0 | HN3: 0 | HO3: 0 | HP3: 0 | HQ3: 0 | HR3: 0 | HS3: 0 | HT3: 0 | HU3: 0 | HV3: 0 | HW3: 0 | HX3: 0 | HY3: 0 | HZ3: 0 | IA3: 0 | IB3: 0 | IC3: 0 | ID3: 0 | IE3: 0 | IF3: 0 | IG3: 0 | IH3: 0 | II3: 0 | IJ3: 0 | IK3: 0 | IL3: 0 | IM3: 0 | IN3: 0 | IO3: 0 | IP3: 0 | IQ3: 0 | IR3: 0 | IS3: 0 | IT3: 0 | IU3: 0 | IV3: 0
A4: 0 | B4: 0 | C4: 0 | D4: 0 | E4: 0 | F4: 0 | G4: 0 | H4: 0 | I4: 0 | J4: 0 | K4: 0 | L4: 0 | M4: 0 | N4: 0 | O4: 0 | P4: 0 | Q4: 0 | R4: 0 | S4: 0 | T4: 0 | U4: 0 | V4: 0 | W4: 0 | X4: 0 | Y4: 0 | Z4: 0 | AA4: 0 | AB4: 0 | AC4: 0 | AD4: 0 | AE4: 0 | AF4: 0 | AG4: 0 | AH4: 0 | AI4: 0 | AJ4: 0 | AK4: 0 | AL4: 0 | AM4: 0 | AN4: 0 | AO4: 0 | AP4: 0 | AQ4: 0 | AR4: 0 | AS4: 0 | AT4: 0 | AU4: 0 | AV4: 0 | AW4: 0 | AX4: 0 | AY4: 0 | AZ4: 0 | BA4: 0 | BB4: 0 | BC4: 0 | BD4: 0 | BE4: 0 | BF4: 0 | BG4: 0 | BH4: 0 | BI4: 0 | BJ4: 0 | BK4: 0 | BL4: 0 | BM4: 0 | BN4: 0 | BO4: 0 | BP4: 0 | BQ4: 0 | BR4: 0 | BS4: 0 | BT4: 0 | BU4: 0 | BV4: 0 | BW4: 0 | BX4: 0 | BY4: 0 | BZ4: 0 | CA4: 0 | CB4: 0 | CC4: 0 | CD4: 0 | CE4: 0 | CF4: 0 | CG4: 0 | CH4: 0 | CI4: 0 | CJ4: 0 | CK4: 0 | CL4: 0 | CM4: 0 | CN4: 0 | CO4: 0 | CP4: 0 | CQ4: 0 | CR4: 0 | CS4: 0 | CT4: 0 | CU4: 0 | CV4: 0 | CW4: 0 | CX4: 0 | CY4: 0 | CZ4: 0 | DA4: 0 | DB4: 0 | DC4: 0 | DD4: 0 | DE4: 0 | DF4: 0 | DG4: 0 | DH4: 0 | DI4: 0 | DJ4: 0 | DK4: 0 | DL4: 0 | DM4: 0 | DN4: 0 | DO4: 0 | DP4: 0 | DQ4: 0 | DR4: 0 | DS4: 0 | DT4: 0 | DU4: 0 | DV4: 0 | DW4: 0 | DX4: 0 | DY4: 0 | DZ4: 0 | EA4: 0 | EB4: 0 | EC4: 0 | ED4: 0 | EE4: 0 | EF4: 0 | EG4: 0 | EH4: 0 | EI4: 0 | EJ4: 0 | EK4: 0 | EL4: 0 | EM4: 0 | EN4: 0 | EO4: 0 | EP4: 0 | EQ4: 0 | ER4: 0 | ES4: 0 | ET4: 0 | EU4: 0 | EV4: 0 | EW4: 0 | EX4: 0 | EY4: 0 | EZ4: 0 | FA4: 0 | FB4: 0 | FC4: 0 | FD4: 0 | FE4: 0 | FF4: 0 | FG4: 0 | FH4: 0 | FI4: 0 | FJ4: 0 | FK4: 0 | FL4: 0 | FM4: 0 | FN4: 0 | FO4: 0 | FP4: 0 | FQ4: 0 | FR4: 0 | FS4: 0 | FT4: 0 | FU4: 0 | FV4: 0 | FW4: 0 | FX4: 0 | FY4: 0 | FZ4: 0 | GA4: 0 | GB4: 0 | GC4: 0 | GD4: 0 | GE4: 0 | GF4: 0 | GG4: 0 | GH4: 0 | GI4: 0 | GJ4: 0 | GK4: 0 | GL4: 0 | GM4: 0 | GN4: 0 | GO4: 0 | GP4: 0 | GQ4: 0 | GR4: 0 | GS4: 0 | GT4: 0 | GU4: 0 | GV4: 0 | GW4: 0 | GX4: 0 | GY4: 0 | GZ4: 0 | HA4: 0 | HB4: 0 | HC4: 0 | HD4: 0 | HE4: 0 | HF4: 0 | HG4: 0 | HH4: 0 | HI4: 0 | HJ4: 0 | HK4: 0 | HL4: 0 | HM4: 0 | HN4: 0 | HO4: 0 | HP4: 0 | HQ4: 0 | HR4: 0 | HS4: 0 | HT4: 0 | HU4: 0 | HV4: 0 | HW4: 0 | HX4: 0 | HY4: 0 | HZ4: 0 | IA4: 0 | IB4: 0 | IC4: 0 | ID4: 0 | IE4: 0 | IF4: 0 | IG4: 0 | IH4: 0 | II4: 0 | IJ4: 0 | IK4: 0 | IL4: 0 | IM4: 0 | IN4: 0 | IO4: 0 | IP4: 0 | IQ4: 0 | IR4: 0 | IS4: 0 | IT4: 0 | IU4: 0 | IV4: 0
A5: 0 | B5: 0 | C5: 0 | D5: 0 | E5: 0 | F5: 0 | G5: 0 | H5: 0 | I5: 0 | J5: 0 | K5: 0 | L5: 0 | M5: 0 | N5: 0 | O5: 0 | P5: 0 | Q5: 0 | R5: 0 | S5: 0 | T5: 0 | U5: 0 | V5: 0 | W5: 0 | X5: 0 | Y5: 0 | Z5: 0 | AA5: 0 | AB5: 0 | AC5: 0 | AD5: 0 | AE5: 0 | AF5: 0 | AG5: 0 | AH5: 0 | AI5: 0 | AJ5: 0 | AK5: 0 | AL5: 0 | AM5: 0 | AN5: 0 | AO5: 0 | AP5: 0 | AQ5: 0 | AR5: 0 | AS5: 0 | AT5: 0 | AU5: 0 | AV5: 0 | AW5: 0 | AX5: 0 | AY5: 0 | AZ5: 0 | BA5: 0 | BB5: 0 | BC5: 0 | BD5: 0 | BE5: 0 | BF5: 0 | BG5: 0 | BH5: 0 | BI5: 0 | BJ5: 0 | BK5: 0 | BL5: 0 | BM5: 0 | BN5: 0 | BO5: 0 | BP5: 0 | BQ5: 0 | BR5: 0 | BS5: 0 | BT5: 0 | BU5: 0 | BV5: 0 | BW5: 0 | BX5: 0 | BY5: 0 | BZ5: 0 | CA5: 0 | CB5: 0 | CC5: 0 | CD5: 0 | CE5: 0 | CF5: 0 | CG5: 0 | CH5: 0 | CI5: 0 | CJ5: 0 | CK5: 0 | CL5: 0 | CM5: 0 | CN5: 0 | CO5: 0 | CP5: 0 | CQ5: 0 | CR5: 0 | CS5: 0 | CT5: 0 | CU5: 0 | CV5: 0 | CW5: 0 | CX5: 0 | CY5: 0 | CZ5: 0 | DA5: 0 | DB5: 0 | DC5: 0 | DD5: 0 | DE5: 0 | DF5: 0 | DG5: 0 | DH5: 0 | DI5: 0 | DJ5: 0 | DK5: 0 | DL5: 0 | DM5: 0 | DN5: 0 | DO5: 0 | DP5: 0 | DQ5: 0 | DR5: 0 | DS5: 0 | DT5: 0 | DU5: 0 | DV5: 0 | DW5: 0 | DX5: 0 | DY5: 0 | DZ5: 0 | EA5: 0 | EB5: 0 | EC5: 0 | ED5: 0 | EE5: 0 | EF5: 0 | EG5: 0 | EH5: 0 | EI5: 0 | EJ5: 0 | EK5: 0 | EL5: 0 | EM5: 0 | EN5: 0 | EO5: 0 | EP5: 0 | EQ5: 0 | ER5: 0 | ES5: 0 | ET5: 0 | EU5: 0 | EV5: 0 | EW5: 0 | EX5: 0 | EY5: 0 | EZ5: 0 | FA5: 0 | FB5: 0 | FC5: 0 | FD5: 0 | FE5: 0 | FF5: 0 | FG5: 0 | FH5: 0 | FI5: 0 | FJ5: 0 | FK5: 0 | FL5: 0 | FM5: 0 | FN5: 0 | FO5: 0 | FP5: 0 | FQ5: 0 | FR5: 0 | FS5: 0 | FT5: 0 | FU5: 0 | FV5: 0 | FW5: 0 | FX5: 0 | FY5: 0 | FZ5: 0 | GA5: 0 | GB5: 0 | GC5: 0 | GD5: 0 | GE5: 0 | GF5: 0 | GG5: 0 | GH5: 0 | GI5: 0 | GJ5: 0 | GK5: 0 | GL5: 0 | GM5: 0 | GN5: 0 | GO5: 0 | GP5: 0 | GQ5: 0 | GR5: 0 | GS5: 0 | GT5: 0 | GU5: 0 | GV5: 0 | GW5: 0 | GX5: 0 | GY5: 0 | GZ5: 0 | HA5: 0 | HB5: 0 | HC5: 0 | HD5: 0 | HE5: 0 | HF5: 0 | HG5: 0 | HH5: 0 | HI5: 0 | HJ5: 0 | HK5: 0 | HL5: 0 | HM5: 0 | HN5: 0 | HO5: 0 | HP5: 0 | HQ5: 0 | HR5: 0 | HS5: 0 | HT5: 0 | HU5: 0 | HV5: 0 | HW5: 0 | HX5: 0 | HY5: 0 | HZ5: 0 | IA5: 0 | IB5: 0 | IC5: 0 | ID5: 0 | IE5: 0 | IF5: 0 | IG5: 0 | IH5: 0 | II5: 0 | IJ5: 0 | IK5: 0 | IL5: 0 | IM5: 0 | IN5: 0 | IO5: 0 | IP5: 0 | IQ5: 0 | IR5: 0 | IS5: 0 | IT5: 0 | IU5: 0 | IV5: 0
A6: 0 | B6: 0 | C6: 0 | D6: 0 | E6: 0 | F6: 0 | G6: 0 | H6: 0 | I6: 0 | J6: 0 | K6: 0 | L6: 0 | M6: 0 | N6: 0 | O6: 0 | P6: 0 | Q6: 0 | R6: 0 | S6: 0 | T6: 0 | U6: 0 | V6: 0 | W6: 0 | X6: 0 | Y6: 0 | Z6: 0 | AA6: 0 | AB6: 0 | AC6: 0 | AD6: 0 | AE6: 0 | AF6: 0 | AG6: 0 | AH6: 0 | AI6: 0 | AJ6: 0 | AK6: 0 | AL6: 0 | AM6: 0 | AN6: 0 | AO6: 0 | AP6: 0 | AQ6: 0 | AR6: 0 | AS6: 0 | AT6: 0 | AU6: 0 | AV6: 0 | AW6: 0 | AX6: 0 | AY6: 0 | AZ6: 0 | BA6: 0 | BB6: 0 | BC6: 0 | BD6: 0 | BE6: 0 | BF6: 0 | BG6: 0 | BH6: 0 | BI6: 0 | BJ6: 0 | BK6: 0 | BL6: 0 | BM6: 0 | BN6: 0 | BO6: 0 | BP6: 0 | BQ6: 0 | BR6: 0 | BS6: 0 | BT6: 0 | BU6: 0 | BV6: 0 | BW6: 0 | BX6: 0 | BY6: 0 | BZ6: 0 | CA6: 0 | CB6: 0 | CC6: 0 | CD6: 0 | CE6: 0 | CF6: 0 | CG6: 0 | CH6: 0 | CI6: 0 | CJ6: 0 | CK6: 0 | CL6: 0 | CM6: 0 | CN6: 0 | CO6: 0 | CP6: 0 | CQ6: 0 | CR6: 0 | CS6: 0 | CT6: 0 | CU6: 0 | CV6: 0 | CW6: 0 | CX6: 0 | CY6: 0 | CZ6: 0 | DA6: 0 | DB6: 0 | DC6: 0 | DD6: 0 | DE6: 0 | DF6: 0 | DG6: 0 | DH6: 0 | DI6: 0 | DJ6: 0 | DK6: 0 | DL6: 0 | DM6: 0 | DN6: 0 | DO6: 0 | DP6: 0 | DQ6: 0 | DR6: 0 | DS6: 0 | DT6: 0 | DU6: 0 | DV6: 0 | DW6: 0 | DX6: 0 | DY6: 0 | DZ6: 0 | EA6: 0 | EB6: 0 | EC6: 0 | ED6: 0 | EE6: 0 | EF6: 0 | EG6: 0 | EH6: 0 | EI6: 0 | EJ6: 0 | EK6: 0 | EL6: 0 | EM6: 0 | EN6: 0 | EO6: 0 | EP6: 0 | EQ6: 0 | ER6: 0 | ES6: 0 | ET6: 0 | EU6: 0 | EV6: 0 | EW6: 0 | EX6: 0 | EY6: 0 | EZ6: 0 | FA6: 0 | FB6: 0 | FC6: 0 | FD6: 0 | FE6: 0 | FF6: 0 | FG6: 0 | FH6: 0 | FI6: 0 | FJ6: 0 | FK6: 0 | FL6: 0 | FM6: 0 | FN6: 0 | FO6: 0 | FP6: 0 | FQ6: 0 | FR6: 0 | FS6: 0 | FT6: 0 | FU6: 0 | FV6: 0 | FW6: 0 | FX6: 0 | FY6: 0 | FZ6: 0 | GA6: 0 | GB6: 0 | GC6: 0 | GD6: 0 | GE6: 0 | GF6: 0 | GG6: 0 | GH6: 0 | GI6: 0 | GJ6: 0 | GK6: 0 | GL6: 0 | GM6: 0 | GN6: 0 | GO6: 0 | GP6: 0 | GQ6: 0 | GR6: 0 | GS6: 0 | GT6: 0 | GU6: 0 | GV6: 0 | GW6: 0 | GX6: 0 | GY6: 0 | GZ6: 0 | HA6: 0 | HB6: 0 | HC6: 0 | HD6: 0 | HE6: 0 | HF6: 0 | HG6: 0 | HH6: 0 | HI6: 0 | HJ6: 0 | HK6: 0 | HL6: 0 | HM6: 0 | HN6: 0 | HO6: 0 | HP6: 0 | HQ6: 0 | HR6: 0 | HS6: 0 | HT6: 0 | HU6: 0 | HV6: 0 | HW6: 0 | HX6: 0 | HY6: 0 | HZ6: 0 | IA6: 0 | IB6: 0 | IC6: 0 | ID6: 0 | IE6: 0 | IF6: 0 | IG6: 0 | IH6: 0 | II6: 0 | IJ6: 0 | IK6: 0 | IL6: 0 | IM6: 0 | IN6: 0 | IO6: 0 | IP6: 0 | IQ6: 0 | IR6: 0 | IS6: 0 | IT6: 0 | IU6: 0 | IV6: 0
A7: 0 | B7: 0 | C7: 0 | D7: 0 | E7: 0 | F7: 0 | G7: 0 | H7: 0 | I7: 0 | J7: 0 | K7: 0 | L7: 0 | M7: 0 | N7: 0 | O7: 0 | P7: 0 | Q7: 0 | R7: 0 | S7: 0 | T7: 0 | U7: 0 | V7: 0 | W7: 0 | X7: 0 | Y7: 0 | Z7: 0 | AA7: 0 | AB7: 0 | AC7: 0 | AD7: 0 | AE7: 0 | AF7: 0 | AG7: 0 | AH7: 0 | AI7: 0 | AJ7: 0 | AK7: 0 | AL7: 0 | AM7: 0 | AN7: 0 | AO7: 0 | AP7: 0 | AQ7: 0 | AR7: 0 | AS7: 0 | AT7: 0 | AU7: 0 | AV7: 0 | AW7: 0 | AX7: 0 | AY7: 0 | AZ7: 0 | BA7: 0 | BB7: 0 | BC7: 0 | BD7: 0 | BE7: 0 | BF7: 0 | BG7: 0 | BH7: 0 | BI7: 0 | BJ7: 0 | BK7: 0 | BL7: 0 | BM7: 0 | BN7: 0 | BO7: 0 | BP7: 0 | BQ7: 0 | BR7: 0 | BS7: 0 | BT7: 0 | BU7: 0 | BV7: 0 | BW7: 0 | BX7: 0 | BY7: 0 | BZ7: 0 | CA7: 0 | CB7: 0 | CC7: 0 | CD7: 0 | CE7: 0 | CF7: 0 | CG7: 0 | CH7: 0 | CI7: 0 | CJ7: 0 | CK7: 0 | CL7: 0 | CM7: 0 | CN7: 0 | CO7: 0 | CP7: 0 | CQ7: 0 | CR7: 0 | CS7: 0 | CT7: 0 | CU7: 0 | CV7: 0 | CW7: 0 | CX7: 0 | CY7: 0 | CZ7: 0 | DA7: 0 | DB7: 0 | DC7: 0 | DD7: 0 | DE7: 0 | DF7: 0 | DG7: 0 | DH7: 0 | DI7: 0 | DJ7: 0 | DK7: 0 | DL7: 0 | DM7: 0 | DN7: 0 | DO7: 0 | DP7: 0 | DQ7: 0 | DR7: 0 | DS7: 0 | DT7: 0 | DU7: 0 | DV7: 0 | DW7: 0 | DX7: 0 | DY7: 0 | DZ7: 0 | EA7: 0 | EB7: 0 | EC7: 0 | ED7: 0 | EE7: 0 | EF7: 0 | EG7: 0 | EH7: 0 | EI7: 0 | EJ7: 0 | EK7: 0 | EL7: 0 | EM7: 0 | EN7: 0 | EO7: 0 | EP7: 0 | EQ7: 0 | ER7: 0 | ES7: 0 | ET7: 0 | EU7: 0 | EV7: 0 | EW7: 0 | EX7: 0 | EY7: 0 | EZ7: 0 | FA7: 0 | FB7: 0 | FC7: 0 | FD7: 0 | FE7: 0 | FF7: 0 | FG7: 0 | FH7: 0 | FI7: 0 | FJ7: 0 | FK7: 0 | FL7: 0 | FM7: 0 | FN7: 0 | FO7: 0 | FP7: 0 | FQ7: 0 | FR7: 0 | FS7: 0 | FT7: 0 | FU7: 0 | FV7: 0 | FW7: 0 | FX7: 0 | FY7: 0 | FZ7: 0 | GA7: 0 | GB7: 0 | GC7: 0 | GD7: 0 | GE7: 0 | GF7: 0 | GG7: 0 | GH7: 0 | GI7: 0 | GJ7: 0 | GK7: 0 | GL7: 0 | GM7: 0 | GN7: 0 | GO7: 0 | GP7: 0 | GQ7: 0 | GR7: 0 | GS7: 0 | GT7: 0 | GU7: 0 | GV7: 0 | GW7: 0 | GX7: 0 | GY7: 0 | GZ7: 0 | HA7: 0 | HB7: 0 | HC7: 0 | HD7: 0 | HE7: 0 | HF7: 0 | HG7: 0 | HH7: 0 | HI7: 0 | HJ7: 0 | HK7: 0 | HL7: 0 | HM7: 0 | HN7: 0 | HO7: 0 | HP7: 0 | HQ7: 0 | HR7: 0 | HS7: 0 | HT7: 0 | HU7: 0 | HV7: 0 | HW7: 0 | HX7: 0 | HY7: 0 | HZ7: 0 | IA7: 0 | IB7: 0 | IC7: 0 | ID7: 0 | IE7: 0 | IF7: 0 | IG7: 0 | IH7: 0 | II7: 0 | IJ7: 0 | IK7: 0 | IL7: 0 | IM7: 0 | IN7: 0 | IO7: 0 | IP7: 0 | IQ7: 0 | IR7: 0 | IS7: 0 | IT7: 0 | IU7: 0 | IV7: 0
A8: 0 | B8: 0 | C8: 0 | D8: 0 | E8: 0 | F8: 0 | G8: 0 | H8: 0 | I8: 0 | J8: 0 | K8: 0 | L8: 0 | M8: 0 | N8: 0 | O8: 0 | P8: 0 | Q8: 0 | R8: 0 | S8: 0 | T8: 0 | U8: 0 | V8: 0 | W8: 0 | X8: 0 | Y8: 0 | Z8: 0 | AA8: 0 | AB8: 0 | AC8: 0 | AD8: 0 | AE8: 0 | AF8: 0 | AG8: 0 | AH8: 0 | AI8: 0 | AJ8: 0 | AK8: 0 | AL8: 0 | AM8: 0 | AN8: 0 | AO8: 0 | AP8: 0 | AQ8: 0 | AR8: 0 | AS8: 0 | AT8: 0 | AU8: 0 | AV8: 0 | AW8: 0 | AX8: 0 | AY8: 0 | AZ8: 0 | BA8: 0 | BB8: 0 | BC8: 0 | BD8: 0 | BE8: 0 | BF8: 0 | BG8: 0 | BH8: 0 | BI8: 0 | BJ8: 0 | BK8: 0 | BL8: 0 | BM8: 0 | BN8: 0 | BO8: 0 | BP8: 0 | BQ8: 0 | BR8: 0 | BS8: 0 | BT8: 0 | BU8: 0 | BV8: 0 | BW8: 0 | BX8: 0 | BY8: 0 | BZ8: 0 | CA8: 0 | CB8: 0 | CC8: 0 | CD8: 0 | CE8: 0 | CF8: 0 | CG8: 0 | CH8: 0 | CI8: 0 | CJ8: 0 | CK8: 0 | CL8: 0 | CM8: 0 | CN8: 0 | CO8: 0 | CP8: 0 | CQ8: 0 | CR8: 0 | CS8: 0 | CT8: 0 | CU8: 0 | CV8: 0 | CW8: 0 | CX8: 0 | CY8: 0 | CZ8: 0 | DA8: 0 | DB8: 0 | DC8: 0 | DD8: 0 | DE8: 0 | DF8: 0 | DG8: 0 | DH8: 0 | DI8: 0 | DJ8: 0 | DK8: 0 | DL8: 0 | DM8: 0 | DN8: 0 | DO8: 0 | DP8: 0 | DQ8: 0 | DR8: 0 | DS8: 0 | DT8: 0 | DU8: 0 | DV8: 0 | DW8: 0 | DX8: 0 | DY8: 0 | DZ8: 0 | EA8: 0 | EB8: 0 | EC8: 0 | ED8: 0 | EE8: 0 | EF8: 0 | EG8: 0 | EH8: 0 | EI8: 0 | EJ8: 0 | EK8: 0 | EL8: 0 | EM8: 0 | EN8: 0 | EO8: 0 | EP8: 0 | EQ8: 0 | ER8: 0 | ES8: 0 | ET8: 0 | EU8: 0 | EV8: 0 | EW8: 0 | EX8: 0 | EY8: 0 | EZ8: 0 | FA8: 0 | FB8: 0 | FC8: 0 | FD8: 0 | FE8: 0 | FF8: 0 | FG8: 0 | FH8: 0 | FI8: 0 | FJ8: 0 | FK8: 0 | FL8: 0 | FM8: 0 | FN8: 0 | FO8: 0 | FP8: 0 | FQ8: 0 | FR8: 0 | FS8: 0 | FT8: 0 | FU8: 0 | FV8: 0 | FW8: 0 | FX8: 0 | FY8: 0 | FZ8: 0 | GA8: 0 | GB8: 0 | GC8: 0 | GD8: 0 | GE8: 0 | GF8: 0 | GG8: 0 | GH8: 0 | GI8: 0 | GJ8: 0 | GK8: 0 | GL8: 0 | GM8: 0 | GN8: 0 | GO8: 0 | GP8: 0 | GQ8: 0 | GR8: 0 | GS8: 0 | GT8: 0 | GU8: 0 | GV8: 0 | GW8: 0 | GX8: 0 | GY8: 0 | GZ8: 0 | HA8: 0 | HB8: 0 | HC8: 0 | HD8: 0 | HE8: 0 | HF8: 0 | HG8: 0 | HH8: 0 | HI8: 0 | HJ8: 0 | HK8: 0 | HL8: 0 | HM8: 0 | HN8: 0 | HO8: 0 | HP8: 0 | HQ8: 0 | HR8: 0 | HS8: 0 | HT8: 0 | HU8: 0 | HV8: 0 | HW8: 0 | HX8: 0 | HY8: 0 | HZ8: 0 | IA8: 0 | IB8: 0 | IC8: 0 | ID8: 0 | IE8: 0 | IF8: 0 | IG8: 0 | IH8: 0 | II8: 0 | IJ8: 0 | IK8: 0 | IL8: 0 | IM8: 0 | IN8: 0 | IO8: 0 | IP8: 0 | IQ8: 0 | IR8: 0 | IS8: 0 | IT8: 0 | IU8: 0 | IV8: 0
A9: 0 | B9: 0 | C9: 0 | D9: 0 | E9: 0 | F9: 0 | G9: 0 | H9: 0 | I9: 0 | J9: 0 | K9: 0 | L9: 0 | M9: 0 | N9: 0 | O9: 0 | P9: 0 | Q9: 0 | R9: 0 | S9: 0 | T9: 0 | U9: 0 | V9: 0 | W9: 0 | X9: 0 | Y9: 0 | Z9: 0 | AA9: 0 | AB9: 0 | AC9: 0 | AD9: 0 | AE9: 0 | AF9: 0 | AG9: 0 | AH9: 0 | AI9: 0 | AJ9: 0 | AK9: 0 | AL9: 0 | AM9: 0 | AN9: 0 | AO9: 0 | AP9: 0 | AQ9: 0 | AR9: 0 | AS9: 0 | AT9: 0 | AU9: 0 | AV9: 0 | AW9: 0 | AX9: 0 | AY9: 0 | AZ9: 0 | BA9: 0 | BB9: 0 | BC9: 0 | BD9: 0 | BE9: 0 | BF9: 0 | BG9: 0 | BH9: 0 | BI9: 0 | BJ9: 0 | BK9: 0 | BL9: 0 | BM9: 0 | BN9: 0 | BO9: 0 | BP9: 0 | BQ9: 0 | BR9: 0 | BS9: 0 | BT9: 0 | BU9: 0 | BV9: 0 | BW9: 0 | BX9: 0 | BY9: 0 | BZ9: 0 | CA9: 0 | CB9: 0 | CC9: 0 | CD9: 0 | CE9: 0 | CF9: 0 | CG9: 0 | CH9: 0 | CI9: 0 | CJ9: 0 | CK9: 0 | CL9: 0 | CM9: 0 | CN9: 0 | CO9: 0 | CP9: 0 | CQ9: 0 | CR9: 0 | CS9: 0 | CT9: 0 | CU9: 0 | CV9: 0 | CW9: 0 | CX9: 0 | CY9: 0 | CZ9: 0 | DA9: 0 | DB9: 0 | DC9: 0 | DD9: 0 | DE9: 0 | DF9: 0 | DG9: 0 | DH9: 0 | DI9: 0 | DJ9: 0 | DK9: 0 | DL9: 0 | DM9: 0 | DN9: 0 | DO9: 0 | DP9: 0 | DQ9: 0 | DR9: 0 | DS9: 0 | DT9: 0 | DU9: 0 | DV9: 0 | DW9: 0 | DX9: 0 | DY9: 0 | DZ9: 0 | EA9: 0 | EB9: 0 | EC9: 0 | ED9: 0 | EE9: 0 | EF9: 0 | EG9: 0 | EH9: 0 | EI9: 0 | EJ9: 0 | EK9: 0 | EL9: 0 | EM9: 0 | EN9: 0 | EO9: 0 | EP9: 0 | EQ9: 0 | ER9: 0 | ES9: 0 | ET9: 0 | EU9: 0 | EV9: 0 | EW9: 0 | EX9: 0 | EY9: 0 | EZ9: 0 | FA9: 0 | FB9: 0 | FC9: 0 | FD9: 0 | FE9: 0 | FF9: 0 | FG9: 0 | FH9: 0 | FI9: 0 | FJ9: 0 | FK9: 0 | FL9: 0 | FM9: 0 | FN9: 0 | FO9: 0 | FP9: 0 | FQ9: 0 | FR9: 0 | FS9: 0 | FT9: 0 | FU9: 0 | FV9: 0 | FW9: 0 | FX9: 0 | FY9: 0 | FZ9: 0 | GA9: 0 | GB9: 0 | GC9: 0 | GD9: 0 | GE9: 0 | GF9: 0 | GG9: 0 | GH9: 0 | GI9: 0 | GJ9: 0 | GK9: 0 | GL9: 0 | GM9: 0 | GN9: 0 | GO9: 0 | GP9: 0 | GQ9: 0 | GR9: 0 | GS9: 0 | GT9: 0 | GU9: 0 | GV9: 0 | GW9: 0 | GX9: 0 | GY9: 0 | GZ9: 0 | HA9: 0 | HB9: 0 | HC9: 0 | HD9: 0 | HE9: 0 | HF9: 0 | HG9: 0 | HH9: 0 | HI9: 0 | HJ9: 0 | HK9: 0 | HL9: 0 | HM9: 0 | HN9: 0 | HO9: 0 | HP9: 0 | HQ9: 0 | HR9: 0 | HS9: 0 | HT9: 0 | HU9: 0 | HV9: 0 | HW9: 0 | HX9: 0 | HY9: 0 | HZ9: 0 | IA9: 0 | IB9: 0 | IC9: 0 | ID9: 0 | IE9: 0 | IF9: 0 | IG9: 0 | IH9: 0 | II9: 0 | IJ9: 0 | IK9: 0 | IL9: 0 | IM9: 0 | IN9: 0 | IO9: 0 | IP9: 0 | IQ9: 0 | IR9: 0 | IS9: 0 | IT9: 0 | IU9: 0 | IV9: 0
A10: 0 | B10: 0 | C10: 0 | D10: 0 | E10: 0 | F10: 0 | G10: 0 | H10: 0 | I10: 0 | J10: 0 | K10: 0 | L10: 0 | M10: 0 | N10: 0 | O10: 0 | P10: 0 | Q10: 0 | R10: 0 | S10: 0 | T10: 0 | U10: 0 | V10: 0 | W10: 0 | X10: 0 | Y10: 0 | Z10: 0 | AA10: 0 | AB10: 0 | AC10: 0 | AD10: 0 | AE10: 0 | AF10: 0 | AG10: 0 | AH10: 0 | AI10: 0 | AJ10: 0 | AK10: 0 | AL10: 0 | AM10: 0 | AN10: 0 | AO10: 0 | AP10: 0 | AQ10: 0 | AR10: 0 | AS10: 0 | AT10: 0 | AU10: 0 | AV10: 0 | AW10: 0 | AX10: 0 | AY10: 0 | AZ10: 0 | BA10: 0 | BB10: 0 | BC10: 0 | BD10: 0 | BE10: 0 | BF10: 0 | BG10: 0 | BH10: 0 | BI10: 0 | BJ10: 0 | BK10: 0 | BL10: 0 | BM10: 0 | BN10: 0 | BO10: 0 | BP10: 0 | BQ10: 0 | BR10: 0 | BS10: 0 | BT10: 0 | BU10: 0 | BV10: 0 | BW10: 0 | BX10: 0 | BY10: 0 | BZ10: 0 | CA10: 0 | CB10: 0 | CC10: 0 | CD10: 0 | CE10: 0 | CF10: 0 | CG10: 0 | CH10: 0 | CI10: 0 | CJ10: 0 | CK10: 0 | CL10: 0 | CM10: 0 | CN10: 0 | CO10: 0 | CP10: 0 | CQ10: 0 | CR10: 0 | CS10: 0 | CT10: 0 | CU10: 0 | CV10: 0 | CW10: 0 | CX10: 0 | CY10: 0 | CZ10: 0 | DA10: 0 | DB10: 0 | DC10: 0 | DD10: 0 | DE10: 0 | DF10: 0 | DG10: 0 | DH10: 0 | DI10: 0 | DJ10: 0 | DK10: 0 | DL10: 0 | DM10: 0 | DN10: 0 | DO10: 0 | DP10: 0 | DQ10: 0 | DR10: 0 | DS10: 0 | DT10: 0 | DU10: 0 | DV10: 0 | DW10: 0 | DX10: 0 | DY10: 0 | DZ10: 0 | EA10: 0 | EB10: 0 | EC10: 0 | ED10: 0 | EE10: 0 | EF10: 0 | EG10: 0 | EH10: 0 | EI10: 0 | EJ10: 0 | EK10: 0 | EL10: 0 | EM10: 0 | EN10: 0 | EO10: 0 | EP10: 0 | EQ10: 0 | ER10: 0 | ES10: 0 | ET10: 0 | EU10: 0 | EV10: 0 | EW10: 0 | EX10: 0 | EY10: 0 | EZ10: 0 | FA10: 0 | FB10: 0 | FC10: 0 | FD10: 0 | FE10: 0 | FF10: 0 | FG10: 0 | FH10: 0 | FI10: 0 | FJ10: 0 | FK10: 0 | FL10: 0 | FM10: 0 | FN10: 0 | FO10: 0 | FP10: 0 | FQ10: 0 | FR10: 0 | FS10: 0 | FT10: 0 | FU10: 0 | FV10: 0 | FW10: 0 | FX10: 0 | FY10: 0 | FZ10: 0 | GA10: 0 | GB10: 0 | GC10: 0 | GD10: 0 | GE10: 0 | GF10: 0 | GG10: 0 | GH10: 0 | GI10: 0 | GJ10: 0 | GK10: 0 | GL10: 0 | GM10: 0 | GN10: 0 | GO10: 0 | GP10: 0 | GQ10: 0 | GR10: 0 | GS10: 0 | GT10: 0 | GU10: 0 | GV10: 0 | GW10: 0 | GX10: 0 | GY10: 0 | GZ10: 0 | HA10: 0 | HB10: 0 | HC10: 0 | HD10: 0 | HE10: 0 | HF10: 0 | HG10: 0 | HH10: 0 | HI10: 0 | HJ10: 0 | HK10: 0 | HL10: 0 | HM10: 0 | HN10: 0 | HO10: 0 | HP10: 0 | HQ10: 0 | HR10: 0 | HS10: 0 | HT10: 0 | HU10: 0 | HV10: 0 | HW10: 0 | HX10: 0 | HY10: 0 | HZ10: 0 | IA10: 0 | IB10: 0 | IC10: 0 | ID10: 0 | IE10: 0 | IF10: 0 | IG10: 0 | IH10: 0 | II10: 0 | IJ10: 0 | IK10: 0 | IL10: 0 | IM10: 0 | IN10: 0 | IO10: 0 | IP10: 0 | IQ10: 0 | IR10: 0 | IS10: 0 | IT10: 0 | IU10: 0 | IV10: 0
A11: 0 | B11: 0 | C11: 0 | D11: 0 | E11: 0 | F11: 0 | G11: 0 | H11: 0 | I11: 0 | J11: 0 | K11: 0 | L11: 0 | M11: 0 | N11: 0 | O11: 0 | P11: 0 | Q11: 0 | R11: 0 | S11: 0 | T11: 0 | U11: 0 | V11: 0 | W11: 0 | X11: 0 | Y11: 0 | Z11: 0 | AA11: 0 | AB11: 0 | AC11: 0 | AD11: 0 | AE11: 0 | AF11: 0 | AG11: 0 | AH11: 0 | AI11: 0 | AJ11: 0 | AK11: 0 | AL11: 0 | AM11: 0 | AN11: 0 | AO11: 0 | AP11: 0 | AQ11: 0 | AR11: 0 | AS11: 0 | AT11: 0 | AU11: 0 | AV11: 0 | AW11: 0 | AX11: 0 | AY11: 0 | AZ11: 0 | BA11: 0 | BB11: 0 | BC11: 0 | BD11: 0 | BE11: 0 | BF11: 0 | BG11: 0 | BH11: 0 | BI11: 0 | BJ11: 0 | BK11: 0 | BL11: 0 | BM11: 0 | BN11: 0 | BO11: 0 | BP11: 0 | BQ11: 0 | BR11: 0 | BS11: 0 | BT11: 0 | BU11: 0 | BV11: 0 | BW11: 0 | BX11: 0 | BY11: 0 | BZ11: 0 | CA11: 0 | CB11: 0 | CC11: 0 | CD11: 0 | CE11: 0 | CF11: 0 | CG11: 0 | CH11: 0 | CI11: 0 | CJ11: 0 | CK11: 0 | CL11: 0 | CM11: 0 | CN11: 0 | CO11: 0 | CP11: 0 | CQ11: 0 | CR11: 0 | CS11: 0 | CT11: 0 | CU11: 0 | CV11: 0 | CW11: 0 | CX11: 0 | CY11: 0 | CZ11: 0 | DA11: 0 | DB11: 0 | DC11: 0 | DD11: 0 | DE11: 0 | DF11: 0 | DG11: 0 | DH11: 0 | DI11: 0 | DJ11: 0 | DK11: 0 | DL11: 0 | DM11: 0 | DN11: 0 | DO11: 0 | DP11: 0 | DQ11: 0 | DR11: 0 | DS11: 0 | DT11: 0 | DU11: 0 | DV11: 0 | DW11: 0 | DX11: 0 | DY11: 0 | DZ11: 0 | EA11: 0 | EB11: 0 | EC11: 0 | ED11: 0 | EE11: 0 | EF11: 0 | EG11: 0 | EH11: 0 | EI11: 0 | EJ11: 0 | EK11: 0 | EL11: 0 | EM11: 0 | EN11: 0 | EO11: 0 | EP11: 0 | EQ11: 0 | ER11: 0 | ES11: 0 | ET11: 0 | EU11: 0 | EV11: 0 | EW11: 0 | EX11: 0 | EY11: 0 | EZ11: 0 | FA11: 0 | FB11: 0 | FC11: 0 | FD11: 0 | FE11: 0 | FF11: 0 | FG11: 0 | FH11: 0 | FI11: 0 | FJ11: 0 | FK11: 0 | FL11: 0 | FM11: 0 | FN11: 0 | FO11: 0 | FP11: 0 | FQ11: 0 | FR11: 0 | FS11: 0 | FT11: 0 | FU11: 0 | FV11: 0 | FW11: 0 | FX11: 0 | FY11: 0 | FZ11: 0 | GA11: 0 | GB11: 0 | GC11: 0 | GD11: 0 | GE11: 0 | GF11: 0 | GG11: 0 | GH11: 0 | GI11: 0 | GJ11: 0 | GK11: 0 | GL11: 0 | GM11: 0 | GN11: 0 | GO11: 0 | GP11: 0 | GQ11: 0 | GR11: 0 | GS11: 0 | GT11: 0 | GU11: 0 | GV11: 0 | GW11: 0 | GX11: 0 | GY11: 0 | GZ11: 0 | HA11: 0 | HB11: 0 | HC11: 0 | HD11: 0 | HE11: 0 | HF11: 0 | HG11: 0 | HH11: 0 | HI11: 0 | HJ11: 0 | HK11: 0 | HL11: 0 | HM11: 0 | HN11: 0 | HO11: 0 | HP11: 0 | HQ11: 0 | HR11: 0 | HS11: 0 | HT11: 0 | HU11: 0 | HV11: 0 | HW11: 0 | HX11: 0 | HY11: 0 | HZ11: 0 | IA11: 0 | IB11: 0 | IC11: 0 | ID11: 0 | IE11: 0 | IF11: 0 | IG11: 0 | IH11: 0 | II11: 0 | IJ11: 0 | IK11: 0 | IL11: 0 | IM11: 0 | IN11: 0 | IO11: 0 | IP11: 0 | IQ11: 0 | IR11: 0 | IS11: 0 | IT11: 0 | IU11: 0 | IV11: 0
A12: 0 | B12: 0 | C12: 0 | D12: 0 | E12: 0 | F12: 0 | G12: 0 | H12: 0 | I12: 0 | J12: 0 | K12: 0 | L12: 0 | M12: 0 | N12: 0 | O12: 0 | P12: 0 | Q12: 0 | R12: 0 | S12: 0 | T12: 0 | U12: 0 | V12: 0 | W12: 0 | X12: 0 | Y12: 0 | Z12: 0 | AA12: 0 | AB12: 0 | AC12: 0 | AD12: 0 | AE12: 0 | AF12: 0 | AG12: 0 | AH12: 0 | AI12: 0 | AJ12: 0 | AK12: 0 | AL12: 0 | AM12: 0 | AN12: 0 | AO12: 0 | AP12: 0 | AQ12: 0 | AR12: 0 | AS12: 0 | AT12: 0 | AU12: 0 | AV12: 0 | AW12: 0 | AX12: 0 | AY12: 0 | AZ12: 0 | BA12: 0 | BB12: 0 | BC12: 0 | BD12: 0 | BE12: 0 | BF12: 0 | BG12: 0 | BH12: 0 | BI12: 0 | BJ12: 0 | BK12: 0 | BL12: 0 | BM12: 0 | BN12: 0 | BO12: 0 | BP12: 0 | BQ12: 0 | BR12: 0 | BS12: 0 | BT12: 0 | BU12: 0 | BV12: 0 | BW12: 0 | BX12: 0 | BY12: 0 | BZ12: 0 | CA12: 0 | CB12: 0 | CC12: 0 | CD12: 0 | CE12: 0 | CF12: 0 | CG12: 0 | CH12: 0 | CI12: 0 | CJ12: 0 | CK12: 0 | CL12: 0 | CM12: 0 | CN12: 0 | CO12: 0 | CP12: 0 | CQ12: 0 | CR12: 0 | CS12: 0 | CT12: 0 | CU12: 0 | CV12: 0 | CW12: 0 | CX12: 0 | CY12: 0 | CZ12: 0 | DA12: 0 | DB12: 0 | DC12: 0 | DD12: 0 | DE12: 0 | DF12: 0 | DG12: 0 | DH12: 0 | DI12: 0 | DJ12: 0 | DK12: 0 | DL12: 0 | DM12: 0 | DN12: 0 | DO12: 0 | DP12: 0 | DQ12: 0 | DR12: 0 | DS12: 0 | DT12: 0 | DU12: 0 | DV12: 0 | DW12: 0 | DX12: 0 | DY12: 0 | DZ12: 0 | EA12: 0 | EB12: 0 | EC12: 0 | ED12: 0 | EE12: 0 | EF12: 0 | EG12: 0 | EH12: 0 | EI12: 0 | EJ12: 0 | EK12: 0 | EL12: 0 | EM12: 0 | EN12: 0 | EO12: 0 | EP12: 0 | EQ12: 0 | ER12: 0 | ES12: 0 | ET12: 0 | EU12: 0 | EV12: 0 | EW12: 0 | EX12: 0 | EY12: 0 | EZ12: 0 | FA12: 0 | FB12: 0 | FC12: 0 | FD12: 0 | FE12: 0 | FF12: 0 | FG12: 0 | FH12: 0 | FI12: 0 | FJ12: 0 | FK12: 0 | FL12: 0 | FM12: 0 | FN12: 0 | FO12: 0 | FP12: 0 | FQ12: 0 | FR12: 0 | FS12: 0 | FT12: 0 | FU12: 0 | FV12: 0 | FW12: 0 | FX12: 0 | FY12: 0 | FZ12: 0 | GA12: 0 | GB12: 0 | GC12: 0 | GD12: 0 | GE12: 0 | GF12: 0 | GG12: 0 | GH12: 0 | GI12: 0 | GJ12: 0 | GK12: 0 | GL12: 0 | GM12: 0 | GN12: 0 | GO12: 0 | GP12: 0 | GQ12: 0 | GR12: 0 | GS12: 0 | GT12: 0 | GU12: 0 | GV12: 0 | GW12: 0 | GX12: 0 | GY12: 0 | GZ12: 0 | HA12: 0 | HB12: 0 | HC12: 0 | HD12: 0 | HE12: 0 | HF12: 0 | HG12: 0 | HH12: 0 | HI12: 0 | HJ12: 0 | HK12: 0 | HL12: 0 | HM12: 0 | HN12: 0 | HO12: 0 | HP12: 0 | HQ12: 0 | HR12: 0 | HS12: 0 | HT12: 0 | HU12: 0 | HV12: 0 | HW12: 0 | HX12: 0 | HY12: 0 | HZ12: 0 | IA12: 0 | IB12: 0 | IC12: 0 | ID12: 0 | IE12: 0 | IF12: 0 | IG12: 0 | IH12: 0 | II12: 0 | IJ12: 0 | IK12: 0 | IL12: 0 | IM12: 0 | IN12: 0 | IO12: 0 | IP12: 0 | IQ12: 0 | IR12: 0 | IS12: 0 | IT12: 0 | IU12: 0 | IV12: 0
A13: 0 | B13: 0 | C13: 0 | D13: 0 | E13: 0 | F13: 0 | G13: 0 | H13: 0 | I13: 0 | J13: 0 | K13: 0 | L13: 0 | M13: 0 | N13: 0 | O13: 0 | P13: 0 | Q13: 0 | R13: 0 | S13: 0 | T13: 0 | U13: 0 | V13: 0 | W13: 0 | X13: 0 | Y13: 0 | Z13: 0 | AA13: 0 | AB13: 0 | AC13: 0 | AD13: 0 | AE13: 0 | AF13: 0 | AG13: 0 | AH13: 0 | AI13: 0 | AJ13: 0 | AK13: 0 | AL13: 0 | AM13: 0 | AN13: 0 | AO13: 0 | AP13: 0 | AQ13: 0 | AR13: 0 | AS13: 0 | AT13: 0 | AU13: 0 | AV13: 0 | AW13: 0 | AX13: 0 | AY13: 0 | AZ13: 0 | BA13: 0 | BB13: 0 | BC13: 0 | BD13: 0 | BE13: 0 | BF13: 0 | BG13: 0 | BH13: 0 | BI13: 0 | BJ13: 0 | BK13: 0 | BL13: 0 | BM13: 0 | BN13: 0 | BO13: 0 | BP13: 0 | BQ13: 0 | BR13: 0 | BS13: 0 | BT13: 0 | BU13: 0 | BV13: 0 | BW13: 0 | BX13: 0 | BY13: 0 | BZ13: 0 | CA13: 0 | CB13: 0 | CC13: 0 | CD13: 0 | CE13: 0 | CF13: 0 | CG13: 0 | CH13: 0 | CI13: 0 | CJ13: 0 | CK13: 0 | CL13: 0 | CM13: 0 | CN13: 0 | CO13: 0 | CP13: 0 | CQ13: 0 | CR13: 0 | CS13: 0 | CT13: 0 | CU13: 0 | CV13: 0 | CW13: 0 | CX13: 0 | CY13: 0 | CZ13: 0 | DA13: 0 | DB13: 0 | DC13: 0 | DD13: 0 | DE13: 0 | DF13: 0 | DG13: 0 | DH13: 0 | DI13: 0 | DJ13: 0 | DK13: 0 | DL13: 0 | DM13: 0 | DN13: 0 | DO13: 0 | DP13: 0 | DQ13: 0 | DR13: 0 | DS13: 0 | DT13: 0 | DU13: 0 | DV13: 0 | DW13: 0 | DX13: 0 | DY13: 0 | DZ13: 0 | EA13: 0 | EB13: 0 | EC13: 0 | ED13: 0 | EE13: 0 | EF13: 0 | EG13: 0 | EH13: 0 | EI13: 0 | EJ13: 0 | EK13: 0 | EL13: 0 | EM13: 0 | EN13: 0 | EO13: 0 | EP13: 0 | EQ13: 0 | ER13: 0 | ES13: 0 | ET13: 0 | EU13: 0 | EV13: 0 | EW13: 0 | EX13: 0 | EY13: 0 | EZ13: 0 | FA13: 0 | FB13: 0 | FC13: 0 | FD13: 0 | FE13: 0 | FF13: 0 | FG13: 0 | FH13: 0 | FI13: 0 | FJ13: 0 | FK13: 0 | FL13: 0 | FM13: 0 | FN13: 0 | FO13: 0 | FP13: 0 | FQ13: 0 | FR13: 0 | FS13: 0 | FT13: 0 | FU13: 0 | FV13: 0 | FW13: 0 | FX13: 0 | FY13: 0 | FZ13: 0 | GA13: 0 | GB13: 0 | GC13: 0 | GD13: 0 | GE13: 0 | GF13: 0 | GG13: 0 | GH13: 0 | GI13: 0 | GJ13: 0 | GK13: 0 | GL13: 0 | GM13: 0 | GN13: 0 | GO13: 0 | GP13: 0 | GQ13: 0 | GR13: 0 | GS13: 0 | GT13: 0 | GU13: 0 | GV13: 0 | GW13: 0 | GX13: 0 | GY13: 0 | GZ13: 0 | HA13: 0 | HB13: 0 | HC13: 0 | HD13: 0 | HE13: 0 | HF13: 0 | HG13: 0 | HH13: 0 | HI13: 0 | HJ13: 0 | HK13: 0 | HL13: 0 | HM13: 0 | HN13: 0 | HO13: 0 | HP13: 0 | HQ13: 0 | HR13: 0 | HS13: 0 | HT13: 0 | HU13: 0 | HV13: 0 | HW13: 0 | HX13: 0 | HY13: 0 | HZ13: 0 | IA13: 0 | IB13: 0 | IC13: 0 | ID13: 0 | IE13: 0 | IF13: 0 | IG13: 0 | IH13: 0 | II13: 0 | IJ13: 0 | IK13: 0 | IL13: 0 | IM13: 0 | IN13: 0 | IO13: 0 | IP13: 0 | IQ13: 0 | IR13: 0 | IS13: 0 | IT13: 0 | IU13: 0 | IV13: 0
... A257: 0 | B257: 0 | C257: 0 | D257: 0 | E257: 0 | F257: 0 | G257: 0 | H257: 0 | I257: 0 | J257: 0 | K257: 0 | L257: 0 | M257: 0 | N257: 0 | O257: 0 | P257: 0 | Q257: 0 | R257: 0 | S257: 0 | T257: 0 | U257: 0 | V257: 0 | W257: 0 | X257: 0 | Y257: 0 | Z257: 0 | AA257: 0 | AB257: 0 | AC257: 0 | AD257: 0 | AE257: 0 | AF257: 0 | AG257: 0 | AH257: 0 | AI257: 0 | AJ257: 0 | AK257: 0 | AL257: 0 | AM257: 0 | AN257: 0 | AO257: 0 | AP257: 0 | AQ257: 0 | AR257: 0 | AS257: 0 | AT257: 0 | AU257: 0 | AV257: 0 | AW257: 0 | AX257: 0 | AY257: 0 | AZ257: 0 | BA257: 0 | BB257: 0 | BC257: 0 | BD257: 0 | BE257: 0 | BF257: 0 | BG257: 0 | BH257: 0 | BI257: 0 | BJ257: 0 | BK257: 0 | BL257: 0 | BM257: 0 | BN257: 0 | BO257: 0 | BP257: 0 | BQ257: 0 | BR257: 0 | BS257: 0 | BT257: 0 | BU257: 0 | BV257: 0 | BW257: 0 | BX257: 0 | BY257: 0 | BZ257: 0 | CA257: 0 | CB257: 0 | CC257: 0 | CD257: 0 | CE257: 0 | CF257: 0 | CG257: 0 | CH257: 0 | CI257: 0 | CJ257: 0 | CK257: 0 | CL257: 0 | CM257: 0 | CN257: 0 | CO257: 0 | CP257: 0 | CQ257: 0 | CR257: 0 | CS257: 0 | CT257: 0 | CU257: 0 | CV257: 0 | CW257: 0 | CX257: 0 | CY257: 0 | CZ257: 0 | DA257: 0 | DB257: 0 | DC257: 0 | DD257: 0 | DE257: 0 | DF257: 0 | DG257: 0 | DH257: 0 | DI257: 0 | DJ257: 0 | DK257: 0 | DL257: 0 | DM257: 0 | DN257: 0 | DO257: 0 | DP257: 0 | DQ257: 0 | DR257: 0 | DS257: 0 | DT257: 0 | DU257: 0 | DV257: 0 | DW257: 0 | DX257: 0 | DY257: 0 | DZ257: 0 | EA257: 0 | EB257: 0 | EC257: 0 | ED257: 0 | EE257: 0 | EF257: 0 | EG257: 0 | EH257: 0 | EI257: 0 | EJ257: 0 | EK257: 0 | EL257: 0 | EM257: 0 | EN257: 0 | EO257: 0 | EP257: 0 | EQ257: 0 | ER257: 0 | ES257: 0 | ET257: 0 | EU257: 0 | EV257: 0 | EW257: 0 | EX257: 0 | EY257: 0 | EZ257: 0 | FA257: 0 | FB257: 0 | FC257: 0 | FD257: 0 | FE257: 0 | FF257: 0 | FG257: 0 | FH257: 0 | FI257: 0 | FJ257: 0 | FK257: 0 | FL257: 0 | FM257: 0 | FN257: 0 | FO257: 0 | FP257: 0 | FQ257: 0 | FR257: 0 | FS257: 0 | FT257: 0 | FU257: 0 | FV257: 0 | FW257: 0 | FX257: 0 | FY257: 0 | FZ257: 0 | GA257: 0 | GB257: 0 | GC257: 0 | GD257: 0 | GE257: 0 | GF257: 0 | GG257: 0 | GH257: 0 | GI257: 0 | GJ257: 0 | GK257: 0 | GL257: 0 | GM257: 0 | GN257: 0 | GO257: 0 | GP257: 0 | GQ257: 0 | GR257: 0 | GS257: 0 | GT257: 0 | GU257: 0 | GV257: 0 | GW257: 0 | GX257: 0 | GY257: 0 | GZ257: 0 | HA257: 0 | HB257: 0 | HC257: 0 | HD257: 0 | HE257: 0 | HF257: 0 | HG257: 0 | HH257: 0 | HI257: 0 | HJ257: 0 | HK257: 0 | HL257: 0 | HM257: 0 | HN257: 0 | HO257: 0 | HP257: 0 | HQ257: 0 | HR257: 0 | HS257: 0 | HT257: 0 | HU257: 0 | HV257: 0 | HW257: 0 | HX257: 0 | HY257: 0 | HZ257: 0 | IA257: 0 | IB257: 0 | IC257: 0 | ID257: 0 | IE257: 0 | IF257: 0 | IG257: 0 | IH257: 0 | II257: 0 | IJ257: 0 | IK257: 0 | IL257: 0 | IM257: 0 | IN257: 0 | IO257: 0 | IP257: 0 | IQ257: 0 | IR257: 0 | IS257: 0 | IT257: 0 | IU257: 0 | IV257: 0

Sheet Instruction Set
B2: Bits | S2: Mnemonic | T2: Name | U2: Argument 1 | V2: Argument 2 | W2: Argument 3 | X2: Notes | AA2: Register Output | AG2: Mem Out | AH2: I/O Output | AJ2: Multiplexers | AQ2: Register Input | AS2: Memory Input | AT2: Program Counter | AX2: Stack | AZ2: I/O Input | BB2: ALU
B3: 15 | C3: 14 | D3: 13 | E3: 12 | F3: 11 | G3: 10 | H3: 9 | I3: 8 | J3: 7 | K3: 6 | L3: 5 | M3: 4 | N3: 3 | O3: 2 | P3: 1 | Q3: 0 | AA3: Enable 1 | AB3: Output 1 | AC3: Enable 2 | AD3: Output 2 | AE3: Pair EN | AF3: Pair Output | AG3: Enable | AH3: Enable | AI3: Select | AJ3: ALU 1 | AK3: ALU 2 | AL3: Register Input | AM3: Mem Read | AN3: Mem In Addr | AO3: Mem In Data | AP3: Push PC +1 | AQ3: Enable | AR3: Select | AS3: Enable | AT3: Hold | AU3: Offset EN | AV3: Override | AX3: Enable | AY3: Mode | AZ3: Enable | BA3: Select | BB3: Enable | BC3: Opcode | BG3: Carry | BH3: Negative | BI3: Overflow | BJ3: Zero
B4: 0 | C4: 0 | D4: 0 | E4: 0 | F4: 0 | G4: 0 | H4: 0 | I4: 0 | J4: 0 | K4: 0 | L4: 0 | M4: 0 | N4: 0 | O4: 0 | P4: 0 | Q4: 0 | S4: NOP | T4: No Operation | U4: - | V4: - | W4: - | AA4: - | AB4: - | AC4: - | AD4: - | AE4: - | AF4: - | AG4: - | AH4: - | AI4: - | AJ4: - | AK4: - | AL4: - | AM4: - | AN4: - | AO4: - | AP4: - | AQ4: - | AR4: - | AS4: - | AT4: - | AU4: - | AV4: - | AW4: PC + 1 | AX4: - | AY4: - | AZ4: - | BA4: - | BB4: - | BC4: - | BD4: - | BE4: - | BF4: - | BG4: - | BH4: - | BI4: - | BJ4: -
B5: 0 | C5: 0 | D5: 0 | E5: 0 | F5: 0 | G5: 0 | H5: 0 | I5: 0 | J5: 0 | K5: 0 | L5: 0 | M5: 0 | N5: 0 | O5: 0 | P5: 0 | Q5: 1 | S5: HLT | T5: Halt | U5: - | V5: - | W5: - | AA5: - | AB5: - | AC5: - | AD5: - | AE5: - | AF5: - | AG5: - | AH5: - | AI5: - | AJ5: - | AK5: - | AL5: - | AM5: - | AN5: - | AO5: - | AP5: - | AQ5: - | AR5: - | AS5: - | AT5: - | AU5: - | AV5: - | AW5: Stop | AX5: - | AY5: - | AZ5: - | BA5: - | BB5: - | BC5: - | BD5: - | BE5: - | BF5: - | BG5: - | BH5: - | BI5: - | BJ5: -
B6: 0 | C6: 0 | D6: 0 | E6: 1 | F6: d | G6: d | H6: d | I6: d | J6: s | K6: s | L6: s | M6: s | N6: 0 | O6: 0 | P6: 0 | Q6: 0 | S6: MOV | T6: Copy Register | U6: Destination Register | V6: Source Register | W6: - | AA6: - | AB6: - | AC6: 1 | AD6: ssss | AE6: - | AF6: - | AG6: - | AH6: - | AI6: - | AJ6: - | AK6: 01 | AL6: - | AM6: - | AN6: - | AO6: - | AP6: - | AQ6: 1 | AR6: dddd | AS6: - | AT6: - | AU6: - | AV6: - | AW6: PC + 1 | AX6: - | AY6: - | AZ6: - | BA6: - | BB6: - | BC6: - | BD6: - | BE6: - | BF6: - | BG6: - | BH6: - | BI6: - | BJ6: -
B7: 0 | C7: 0 | D7: 0 | E7: 1 | F7: d | G7: d | H7: d | I7: d | J7: s | K7: s | L7: s | M7: s | N7: 0 | O7: 0 | P7: 0 | Q7: 1 | S7: CMP | T7: Compare | U7: Destination Register | V7: Source Register | W7: - | X7: dddd-ssss | AA7: 1 | AB7: dddd | AC7: 1 | AD7: ssss | AE7: - | AF7: - | AG7: - | AH7: - | AI7: - | AJ7: 10 | AK7: 01 | AL7: - | AM7: - | AN7: - | AO7: - | AP7: - | AQ7: - | AR7: - | AS7: - | AT7: - | AU7: - | AV7: - | AW7: PC + 1 | AX7: - | AY7: - | AZ7: - | BA7: - | BB7: 1 | BC7: 0 | BD7: 0 | BE7: 0 | BF7: 1 | BG7: 1 | BH7: 1 | BI7: 1 | BJ7: 1
B8: 0 | C8: 0 | D8: 0 | E8: 1 | F8: s | G8: s | H8: s | I8: s | J8: 0 | K8: 0 | L8: 0 | M8: 0 | N8: 0 | O8: 0 | P8: 1 | Q8: 0 | S8: PUSH | T8: Push to Stack | U8: Source Register | V8: - | W8: - | AA8: 1 | AB8: ssss | AC8: - | AD8: - | AE8: - | AF8: - | AG8: - | AH8: - | AI8: - | AJ8: - | AK8: - | AL8: - | AM8: - | AN8: 01 | AO8: 00 | AP8: - | AQ8: - | AR8: - | AS8: 1 | AT8: - | AU8: - | AV8: - | AW8: PC + 1 | AX8: - | AY8: SP - 1 | AZ8: - | BA8: - | BB8: - | BC8: - | BD8: - | BE8: - | BF8: - | BG8: - | BH8: - | BI8: - | BJ8: -
B9: 0 | C9: 0 | D9: 0 | E9: 1 | F9: d | G9: d | H9: d | I9: d | J9: 0 | K9: 0 | L9: 0 | M9: 0 | N9: 0 | O9: 0 | P9: 1 | Q9: 1 | S9: POP | T9: Pop from Stack | U9: Destination Register | V9: - | W9: - | AA9: - | AB9: - | AC9: - | AD9: - | AE9: - | AF9: - | AG9: 1 | AH9: - | AI9: - | AJ9: - | AK9: - | AL9: 10 | AM9: 01 | AN9: - | AO9: - | AP9: - | AQ9: 1 | AR9: dddd | AS9: - | AT9: - | AU9: - | AV9: - | AW9: PC + 1 | AX9: - | AY9: SP + 1 | AZ9: - | BA9: - | BB9: - | BC9: - | BD9: - | BE9: - | BF9: - | BG9: - | BH9: - | BI9: - | BJ9: -
B10: 0 | C10: 0 | D10: 0 | E10: 1 | F10: d | G10: d | H10: d | I10: d | J10: i | K10: i | L10: i | M10: i | N10: 0 | O10: 1 | P10: 0 | Q10: 0 | S10: IN | T10: Load from I/O to Register | U10: Destination Register | V10: I/O Address | W10: - | AA10: - | AB10: - | AC10: - | AD10: - | AE10: - | AF10: - | AG10: - | AH10: 1 | AI10: iiii | AJ10: - | AK10: - | AL10: 01 | AM10: - | AN10: - | AO10: - | AP10: - | AQ10: 1 | AR10: dddd | AS10: - | AT10: - | AU10: - | AV10: - | AW10: PC + 1 | AX10: - | AY10: - | AZ10: - | BA10: - | BB10: - | BC10: - | BD10: - | BE10: - | BF10: - | BG10: - | BH10: - | BI10: - | BJ10: -
B11: 0 | C11: 0 | D11: 0 | E11: 1 | F11: s | G11: s | H11: s | I11: s | J11: i | K11: i | L11: i | M11: i | N11: 0 | O11: 1 | P11: 0 | Q11: 1 | S11: OUT | T11: Store to I/O from Register | U11: Source Register | V11: I/O Address | W11: - | AA11: 1 | AB11: ssss | AC11: - | AD11: - | AE11: - | AF11: - | AG11: - | AH11: - | AI11: - | AJ11: - | AK11: - | AL11: - | AM11: - | AN11: - | AO11: - | AP11: - | AQ11: - | AR11: - | AS11: - | AT11: - | AU11: - | AV11: - | AW11: PC + 1 | AX11: - | AY11: - | AZ11: 1 | BA11: iiii | BB11: - | BC11: - | BD11: - | BE11: - | BF11: - | BG11: - | BH11: - | BI11: - | BJ11: -
B12: 0 | C12: 0 | D12: 1 | E12: 0 | F12: d | G12: d | H12: d | I12: d | J12: s | K12: s | L12: s | M12: s | N12: 0 | O12: 0 | P12: 0 | Q12: 0 | S12: NOT | T12: One's Complement | U12: Destination Register | V12: - | W12: - | X12: 0xff - x | AA12: - | AB12: - | AC12: 1 | AD12: ssss | AE12: - | AF12: - | AG12: - | AH12: - | AI12: - | AJ12: 01 | AK12: 01 | AL12: 00 | AM12: - | AN12: - | AO12: - | AP12: - | AQ12: 1 | AR12: dddd | AS12: - | AT12: - | AU12: - | AV12: - | AW12: PC + 1 | AX12: - | AY12: - | AZ12: - | BA12: - | BB12: 1 | BC12: 0 | BD12: 0 | BE12: 0 | BF12: 1 | BG12: 0 | BH12: 1 | BI12: 0 | BJ12: 1
B13: 0 | C13: 0 | D13: 1 | E13: 0 | F13: d | G13: d | H13: d | I13: d | J13: s | K13: s | L13: s | M13: s | N13: 0 | O13: 0 | P13: 0 | Q13: 1 | S13: NEG | T13: Two's Complement | U13: Destination Register | V13: - | W13: - | X13: 0x00 - x | AA13: - | AB13: - | AC13: 1 | AD13: ssss | AE13: - | AF13: - | AG13: - | AH13: - | AI13: - | AJ13: 00 | AK13: 01 | AL13: 00 | AM13: - | AN13: - | AO13: - | AP13: - | AQ13: 1 | AR13: dddd | AS13: - | AT13: - | AU13: - | AV13: - | AW13: PC + 1 | AX13: - | AY13: - | AZ13: - | BA13: - | BB13: 1 | BC13: 0 | BD13: 0 | BE13: 0 | BF13: 1 | BG13: 1 | BH13: 1 | BI13: 1 | BJ13: 1
B14: 0 | C14: 0 | D14: 1 | E14: 0 | F14: d | G14: d | H14: d | I14: d | J14: 0 | K14: 0 | L14: 0 | M14: 0 | N14: 0 | O14: 0 | P14: 1 | Q14: 0 | S14: INC | T14: Increment | U14: Destination Register | V14: - | W14: - | X14: Add Imm 1 | AA14: 1 | AB14: dddd | AC14: - | AD14: - | AE14: - | AF14: - | AG14: - | AH14: - | AI14: - | AJ14: 10 | AK14: 00 | AL14: 00 | AM14: - | AN14: - | AO14: - | AP14: - | AQ14: 1 | AR14: dddd | AS14: - | AT14: - | AU14: - | AV14: - | AW14: PC + 1 | AX14: - | AY14: - | AZ14: - | BA14: - | BB14: 1 | BC14: 0 | BD14: 0 | BE14: 0 | BF14: 0 | BG14: 0 | BH14: 1 | BI14: 1 | BJ14: 1
B15: 0 | C15: 0 | D15: 1 | E15: 0 | F15: d | G15: d | H15: d | I15: d | J15: 0 | K15: 0 | L15: 0 | M15: 0 | N15: 0 | O15: 0 | P15: 1 | Q15: 1 | S15: DEC | T15: Decrement | U15: Destination Register | V15: - | W15: - | X15: Sub Imm 1 | AA15: 1 | AB15: dddd | AC15: - | AD15: - | AE15: - | AF15: - | AG15: - | AH15: - | AI15: - | AJ15: 10 | AK15: 00 | AL15: 00 | AM15: - | AN15: - | AO15: - | AP15: - | AQ15: 1 | AR15: dddd | AS15: - | AT15: - | AU15: - | AV15: - | AW15: PC + 1 | AX15: - | AY15: - | AZ15: - | BA15: - | BB15: 1 | BC15: 0 | BD15: 0 | BE15: 0 | BF15: 1 | BG15: 0 | BH15: 1 | BI15: 1 | BJ15: 1
B16: 0 | C16: 0 | D16: 1 | E16: 0 | F16: d | G16: d | H16: d | I16: d | J16: 0 | K16: 0 | L16: 0 | M16: 0 | N16: 0 | O16: 1 | P16: 0 | Q16: 0 | S16: SHL | T16: Shift Left | U16: Destination Register | V16: - | W16: - | AA16: 1 | AB16: dddd | AC16: - | AD16: - | AE16: - | AF16: - | AG16: - | AH16: - | AI16: - | AJ16: 10 | AK16: - | AL16: 00 | AM16: - | AN16: - | AO16: - | AP16: - | AQ16: 1 | AR16: dddd | AS16: - | AT16: - | AU16: - | AV16: - | AW16: PC + 1 | AX16: - | AY16: - | AZ16: - | BA16: - | BB16: 1 | BC16: 0 | BD16: 1 | BE16: 1 | BF16: 1 | BG16: 1 | BH16: 0 | BI16: 1 | BJ16: 1
B17: 0 | C17: 0 | D17: 1 | E17: 0 | F17: d | G17: d | H17: d | I17: d | J17: 0 | K17: 0 | L17: 0 | M17: 0 | N17: 0 | O17: 1 | P17: 0 | Q17: 1 | S17: SHR | T17: Shift Right | U17: Destination Register | V17: - | W17: - | AA17: 1 | AB17: dddd | AC17: - | AD17: - | AE17: - | AF17: - | AG17: - | AH17: - | AI17: - | AJ17: 10 | AK17: - | AL17: 00 | AM17: - | AN17: - | AO17: - | AP17: - | AQ17: 1 | AR17: dddd | AS17: - | AT17: - | AU17: - | AV17: - | AW17: PC + 1 | AX17: - | AY17: - | AZ17: - | BA17: - | BB17: 1 | BC17: 1 | BD17: 0 | BE17: 0 | BF17: 0 | BG17: 1 | BH17: 0 | BI17: 0 | BJ17: 1
B18: 0 | C18: 0 | D18: 1 | E18: 0 | F18: d | G18: d | H18: d | I18: d | J18: 0 | K18: 0 | L18: 0 | M18: 0 | N18: 0 | O18: 1 | P18: 1 | Q18: 0 | S18: ROL | T18: Rotate Left | U18: Destination Register | V18: - | W18: - | X18: Rotate Through Carry | AA18: 1 | AB18: dddd | AC18: - | AD18: - | AE18: - | AF18: - | AG18: - | AH18: - | AI18: - | AJ18: 10 | AK18: - | AL18: 00 | AM18: - | AN18: - | AO18: - | AP18: - | AQ18: 1 | AR18: dddd | AS18: - | AT18: - | AU18: - | AV18: - | AW18: PC + 1 | AX18: - | AY18: - | AZ18: - | BA18: - | BB18: 1 | BC18: 1 | BD18: 0 | BE18: 1 | BF18: 0 | BG18: 1 | BH18: 0 | BI18: 1 | BJ18: 0
B19: 0 | C19: 0 | D19: 1 | E19: 0 | F19: d | G19: d | H19: d | I19: d | J19: 0 | K19: 0 | L19: 0 | M19: 0 | N19: 0 | O19: 1 | P19: 1 | Q19: 1 | S19: ROR | T19: Rotate Right | U19: Destination Register | V19: - | W19: - | X19: Rotate Through Carry | AA19: 1 | AB19: dddd | AC19: - | AD19: - | AE19: - | AF19: - | AG19: - | AH19: - | AI19: - | AJ19: 10 | AK19: - | AL19: 00 | AM19: - | AN19: - | AO19: - | AP19: - | AQ19: 1 | AR19: dddd | AS19: - | AT19: - | AU19: - | AV19: - | AW19: PC + 1 | AX19: - | AY19: - | AZ19: - | BA19: - | BB19: 1 | BC19: 1 | BD19: 0 | BE19: 1 | BF19: 1 | BG19: 1 | BH19: 0 | BI19: 1 | BJ19: 0
B20: 0 | C20: 0 | D20: 1 | E20: 0 | F20: d | G20: d | H20: d | I20: d | J20: 0 | K20: 0 | L20: 0 | M20: 0 | N20: 1 | O20: 0 | P20: 0 | Q20: 0 | S20: ASR | T20: Arithmetic Shift Right | U20: Destination Register | V20: - | W20: - | AA20: 1 | AB20: dddd | AC20: - | AD20: - | AE20: - | AF20: - | AG20: - | AH20: - | AI20: - | AJ20: 10 | AK20: - | AL20: 00 | AM20: - | AN20: - | AO20: - | AP20: - | AQ20: 1 | AR20: dddd | AS20: - | AT20: - | AU20: - | AV20: - | AW20: PC + 1 | AX20: - | AY20: - | AZ20: - | BA20: - | BB20: 1 | BC20: 1 | BD20: 0 | BE20: 0 | BF20: 1 | BG20: 1 | BH20: 0 | BI20: 0 | BJ20: 1
B21: 0 | C21: 0 | D21: 1 | E21: 0 | F21: d | G21: d | H21: d | I21: d | J21: s | K21: s | L21: s | M21: s | N21: 1 | O21: 0 | P21: 0 | Q21: 1 | S21: ADD | T21: Add | U21: Destination Register | V21: Source Register | W21: - | AA21: 1 | AB21: dddd | AC21: 1 | AD21: ssss | AE21: - | AF21: - | AG21: - | AH21: - | AI21: - | AJ21: 10 | AK21: 01 | AL21: 00 | AM21: - | AN21: - | AO21: - | AP21: - | AQ21: 1 | AR21: dddd | AS21: - | AT21: - | AU21: - | AV21: - | AW21: PC + 1 | AX21: - | AY21: - | AZ21: - | BA21: - | BB21: 1 | BC21: 0 | BD21: 0 | BE21: 0 | BF21: 0 | BG21: 1 | BH21: 1 | BI21: 1 | BJ21: 1
B22: 0 | C22: 0 | D22: 1 | E22: 0 | F22: d | G22: d | H22: d | I22: d | J22: s | K22: s | L22: s | M22: s | N22: 1 | O22: 0 | P22: 1 | Q22: 0 | S22: SUB | T22: Subtract | U22: Destination Register | V22: Source Register | W22: - | AA22: 1 | AB22: dddd | AC22: 1 | AD22: ssss | AE22: - | AF22: - | AG22: - | AH22: - | AI22: - | AJ22: 10 | AK22: 01 | AL22: 00 | AM22: - | AN22: - | AO22: - | AP22: - | AQ22: 1 | AR22: dddd | AS22: - | AT22: - | AU22: - | AV22: - | AW22: PC + 1 | AX22: - | AY22: - | AZ22: - | BA22: - | BB22: 1 | BC22: 0 | BD22: 0 | BE22: 0 | BF22: 1 | BG22: 1 | BH22: 1 | BI22: 1 | BJ22: 1
B23: 0 | C23: 0 | D23: 1 | E23: 0 | F23: d | G23: d | H23: d | I23: d | J23: s | K23: s | L23: s | M23: s | N23: 1 | O23: 0 | P23: 1 | Q23: 1 | S23: ADC | T23: Add With Carry | U23: Destination Register | V23: Source Register | W23: - | AA23: 1 | AB23: dddd | AC23: 1 | AD23: ssss | AE23: - | AF23: - | AG23: - | AH23: - | AI23: - | AJ23: 10 | AK23: 01 | AL23: 00 | AM23: - | AN23: - | AO23: - | AP23: - | AQ23: 1 | AR23: dddd | AS23: - | AT23: - | AU23: - | AV23: - | AW23: PC + 1 | AX23: - | AY23: - | AZ23: - | BA23: - | BB23: 1 | BC23: 0 | BD23: 0 | BE23: 1 | BF23: 0 | BG23: 1 | BH23: 1 | BI23: 1 | BJ23: 1
B24: 0 | C24: 0 | D24: 1 | E24: 0 | F24: d | G24: d | H24: d | I24: d | J24: s | K24: s | L24: s | M24: s | N24: 1 | O24: 1 | P24: 0 | Q24: 0 | S24: SUBC | T24: Subtract With Carry | U24: Destination Register | V24: Source Register | W24: - | AA24: 1 | AB24: dddd | AC24: 1 | AD24: ssss | AE24: - | AF24: - | AG24: - | AH24: - | AI24: - | AJ24: 10 | AK24: 01 | AL24: 00 | AM24: - | AN24: - | AO24: - | AP24: - | AQ24: 1 | AR24: dddd | AS24: - | AT24: - | AU24: - | AV24: - | AW24: PC + 1 | AX24: - | AY24: - | AZ24: - | BA24: - | BB24: 1 | BC24: 0 | BD24: 0 | BE24: 1 | BF24: 1 | BG24: 1 | BH24: 1 | BI24: 1 | BJ24: 1
B25: 0 | C25: 0 | D25: 1 | E25: 0 | F25: d | G25: d | H25: d | I25: d | J25: s | K25: s | L25: s | M25: s | N25: 1 | O25: 1 | P25: 0 | Q25: 1 | S25: AND | T25: AND | U25: Destination Register | V25: Source Register | W25: - | AA25: 1 | AB25: dddd | AC25: 1 | AD25: ssss | AE25: - | AF25: - | AG25: - | AH25: - | AI25: - | AJ25: 10 | AK25: 01 | AL25: 00 | AM25: - | AN25: - | AO25: - | AP25: - | AQ25: 1 | AR25: dddd | AS25: - | AT25: - | AU25: - | AV25: - | AW25: PC + 1 | AX25: - | AY25: - | AZ25: - | BA25: - | BB25: 1 | BC25: 0 | BD25: 1 | BE25: 0 | BF25: 0 | BG25: 0 | BH25: 1 | BI25: 0 | BJ25: 1
B26: 0 | C26: 0 | D26: 1 | E26: 0 | F26: d | G26: d | H26: d | I26: d | J26: s | K26: s | L26: s | M26: s | N26: 1 | O26: 1 | P26: 1 | Q26: 0 | S26: OR | T26: OR | U26: Destination Register | V26: Source Register | W26: - | AA26: 1 | AB26: dddd | AC26: 1 | AD26: ssss | AE26: - | AF26: - | AG26: - | AH26: - | AI26: - | AJ26: 10 | AK26: 01 | AL26: 00 | AM26: - | AN26: - | AO26: - | AP26: - | AQ26: 1 | AR26: dddd | AS26: - | AT26: - | AU26: - | AV26: - | AW26: PC + 1 | AX26: - | AY26: - | AZ26: - | BA26: - | BB26: 1 | BC26: 0 | BD26: 1 | BE26: 0 | BF26: 1 | BG26: 0 | BH26: 1 | BI26: 0 | BJ26: 1
B27: 0 | C27: 0 | D27: 1 | E27: 0 | F27: d | G27: d | H27: d | I27: d | J27: s | K27: s | L27: s | M27: s | N27: 1 | O27: 1 | P27: 1 | Q27: 1 | S27: XOR | T27: XOR | U27: Destination Register | V27: Source Register | W27: - | AA27: 1 | AB27: dddd | AC27: 1 | AD27: ssss | AE27: - | AF27: - | AG27: - | AH27: - | AI27: - | AJ27: 10 | AK27: 01 | AL27: 00 | AM27: - | AN27: - | AO27: - | AP27: - | AQ27: 1 | AR27: dddd | AS27: - | AT27: - | AU27: - | AV27: - | AW27: PC + 1 | AX27: - | AY27: - | AZ27: - | BA27: - | BB27: 1 | BC27: 0 | BD27: 1 | BE27: 1 | BF27: 0 | BG27: 0 | BH27: 1 | BI27: 0 | BJ27: 1
B28: 0 | C28: 1 | D28: 0 | E28: 0 | F28: p | G28: p | H28: p | I28: p | J28: p | K28: p | L28: p | M28: p | N28: p | O28: p | P28: p | Q28: p | S28: JMP | T28: Jump | U28: ROM 12-Bit Address | W28: - | AA28: - | AB28: - | AC28: - | AD28: - | AE28: - | AF28: - | AG28: - | AH28: - | AI28: - | AJ28: - | AK28: - | AL28: - | AM28: - | AN28: - | AO28: - | AP28: - | AQ28: - | AR28: - | AS28: - | AT28: - | AU28: - | AV28: 1/1 | AW28: Address | AX28: - | AY28: - | AZ28: - | BA28: - | BB28: - | BC28: - | BD28: - | BE28: - | BF28: - | BG28: - | BH28: - | BI28: - | BJ28: -
B29: 0 | C29: 1 | D29: 0 | E29: 1 | F29: p | G29: p | H29: p | I29: p | J29: p | K29: p | L29: p | M29: p | N29: p | O29: p | P29: p | Q29: p | S29: CALL | T29: Call | U29: ROM 12-Bit Address | W29: - | X29: 2 Cycles | AA29: - | AB29: - | AC29: - | AD29: - | AE29: - | AF29: - | AG29: - | AH29: - | AI29: - | AJ29: - | AK29: - | AL29: - | AM29: - | AN29: 01 | AO29: 01 -> 10 | AP29: 1 | AQ29: - | AR29: - | AS29: 1 | AT29: 1 | AU29: - | AV29: 1/1 | AW29: Address | AX29: - | AY29: SP - 2 | AZ29: - | BA29: - | BB29: - | BC29: - | BD29: - | BE29: - | BF29: - | BG29: - | BH29: - | BI29: - | BJ29: -
B30: 0 | C30: 1 | D30: 1 | E30: 0 | F30: 0 | G30: 0 | H30: 0 | I30: 0 | J30: 0 | K30: 0 | L30: 0 | M30: 0 | N30: 0 | O30: 0 | P30: 0 | Q30: 0 | S30: RET | T30: Return | U30: - | V30: - | W30: - | X30: 2 Cycles | AA30: - | AB30: - | AC30: - | AD30: - | AE30: - | AF30: - | AG30: 1 | AH30: - | AI30: - | AJ30: - | AK30: - | AL30: - | AM30: 01 | AN30: - | AO30: - | AP30: - | AQ30: - | AR30: - | AS30: - | AT30: 1 | AU30: - | AV30: 1/1 | AW30: From Stack | AX30: - | AY30: SP + 2 | AZ30: - | BA30: - | BB30: - | BC30: - | BD30: - | BE30: - | BF30: - | BG30: - | BH30: - | BI30: - | BJ30: -
